Workbook

Sheet 25메인호텔
A1: 호텔명 | B1: 등급 | C1: 요금 | D1: 특이사항
A2: 머큐어 티히티 | B2: 4 | C2: 160 | F2: Momentus | G2: 190 | H2: 180
A3: IBIS 노베나 | B3: 4 | C3: 160 | F3: Aloft Novena | G3: 180 | H3: 180
A4: Alfot | B4: 4 | C4: 180 | D4: 이스트 윙 ( 웨스트 200 ) | F4: Mercure Stevens | G4: 180 | H4: 180
A5: 머큐어스티븐스 | B5: 4 | C5: 180 | D5: ~ 3월까지 | F5: M Hotel City Centre | G5: 230 | H5: 230
A6: 모멘투스 | B6: 4 | C6: 180/190 | D6: 트윈게런티 (200) | F6: Concorde Hotel | G6: 230 | H6: 230
A7: 오아시아노베나 | B7: 4 | C7: 210 | D7: 데일리 9방 얼랏먼트 | F7: Oasia Novena | G7: 210 | H7: 210
A8: M호텔 | B8: 4 | C8: 215 | D8: 1월~3월까지 | F8: Orchid Hotel | G8: 220 | H8: 220
A9: 아마라 | B9: 5 | C9: 230 | F9: Amara Singapore | G9: 230 | H9: 230
A10: 오아시아센토사 | B10: 5 | C10: 260 | D10: 데일리 10방 하드 | F10: Orchard Hotel | G10: 240 | H10: 240
F11: Grand Copthorne | G11: 240 | H11: 240
F12: Mercure Tyrwhitt | G12: 170 | H12: 170
F13: Hotel Boss | G13: 185 | H13: 185
F14: V Hotel Lavender | G14: 185 | H14: 185
F15: IbIs Novena | G15: 155 | H15: 155
F16: IbIs bencoolen | G16: 185 | H16: 185
F17: Oasia Sentosa | G17: 240 | H17: 240
F18: Swissotel The stamford | G18: 540 | H18: 540

Sheet 가이드&차량
A1: 환율 | B1: 1100
A2: 구분 | B2: 일정 | C2: SGD | H2: 45 | I2: 49 | J2: 23 | K2: 13
A3: 한국인 가이드 | B3: 공항미팅/공항샌딩 | C3: 150 | G3: 150 | H3: 280 | I3: 290 | J3: 200 | K3: 120
B4: 4시간 이하 | C4: 250 | D4: 1 | E4: 5 | G4: 375 | H4: 630 | I4: 680 | J4: 530 | K4: 420
B5: 8시간 이하 | C5: 300 | G5: 375 | H5: 630 | I5: 680 | J5: 530 | K5: 420
B6: 10시간 | C6: 375 | G6: =350+150 -> 500 | H6: 630 | I6: 680 | J6: 530 | K6: 420
B7: 12시간 | C7: =C6+50 -> 425 | G7: =SUM(G3:G6) -> 1400 | H7: =SUM(H3:H6) -> 2170 | I7: =SUM(I3:I6) -> 2330 | J7: =SUM(J3:J6) -> 1790 | K7: =SUM(K3:K6) -> 1380
B8: 추가 시간당 | C8: 40
B9: 할증 택시비( 23:00 ~ 08 :00 ) | C9: 50
A11: 현지 영어 가이드 | B11: 공항미팅/공항샌딩 | C11: 150
B12: 4시간 이하 | C12: 300 | H12: =IF(D4+E4<8,'가이드&차량'!C43, IF(D4+E4<=14,'가이드&차량'!C35,'가이드&차량'!C19)) -> 120
B13: 8시간 이하 | C13: 350
B14: 10시간 | C14: 400
B15: 12시간 | C15: =C14+80 -> 480 | H15: =IF(D4+E4<8,'가이드&차량'!C47, IF(D4+E4<=14,'가이드&차량'!C39,'가이드&차량'!C23)) -> 430
B16: 추가 시간당 | C16: 40
B17: 할증( 23:00 ~ 08 :00 ) | C17: 50
A19: 45인 버스 ( 34명 ) | B19: 공항미팅/공항샌딩 | C19: 280
B20: 4시간 이하 | C20: 400
B21: 8시간 이하 | C21: 500 | G21: 1. 엑셀 H2에 입력한 날짜 요일에 따라서 AC2, AD2에 입력한 주중/주말 요금을 반영한다.
B22: 10시간 | C22: 555 | G22: 2. H2에 입력한 날짜가 W3에서 X3까지의 날짜 구간안에 들어가면 Z3 을 추가하여 보여준다.
B23: 12시간 | C23: 630 | G23: 3. H2에 입력한 날짜가 W4에서 X4까지의 날짜 구간안에 들어가면 Z4 을 추가하여 보여준다.
B24: 추가 시간당 | C24: 75 | G24: 4. H2에 입력한 날짜가 W5에서 X5까지의 날짜 구간안에 들어가면 Z5 을 추가하여 보여준다.
B25: 할증( 23:00 ~ 08 :00 ) | C25: 80 | G25: 5. H2에 입력한 날짜가 W6에서 X6까지의 날짜 구간안에 들어가면 Z6 을 추가하여 보여준다.
G26: 6. H2에 입력한 날짜가 W7에서 X7까지의 날짜 구간안에 들어가면 Z7 을 추가하여 보여준다.
A27: 49인 버스 ( 40명 ) | B27: 공항미팅/공항샌딩 | C27: 290 | G27: 7. H2에 입력한8에서 X8까지의 날짜 구간안에 들어가면 Z8 을 추가하여 보여준다.
B28: 4시간 이하 | C28: 450 | G28: 8. H2에 입력한 날짜가 W9에서 X9까지의 날짜 구간안에 들어가면 Z9 을 추가하여 보여준다.
B29: 8시간 이하 | C29: 550 | G29: 9. H2에 입력한 날짜가 W10에서 X10까지의 날짜 구간안에 들어가면 Z10 을 추가하여 보여준다.
B30: 10시간 | C30: 595 | G30: 10. 최종 요금이 요금 값이 1 보다 작은 경우 Surcharg Check 를 표시한다
B31: 12시간 | C31: 680
B32: 추가 시간당 | C32: 85
B33: 할증( 23:00 ~ 08 :00 ) | C33: 80
A35: 23인 버스 ( 14명 ) | B35: 공항미팅/공항샌딩 | C35: 200
B36: 4시간 이하 | C36: 350
B37: 8시간 이하 | C37: 400
B38: 10시간 | C38: 465
B39: 12시간 | C39: 530
B40: 추가 시간당 | C40: 65
B41: 할증( 23:00 ~ 08 :00 ) | C41: 65
A43: 13인 승합차 ( 8명 ) | B43: 공항미팅/공항샌딩 | C43: 120
B44: 4시간 이하 | C44: 250
...

Sheet 서차지
B1: Update : 25-12-20
B2: EVENT | C2: 시작일 | D2: 마감일 | E2: 실제 행사일
B3: World Paralympic Swimming | C3: 45921 | D3: 45562 | E3: 21 – 27 September 2025
B4: Singapore Formula One (F1) | C4: 45932 | D4: 45935 | E4: 02 Oct - 05 Oct, 2025
B5: ITB Asia | C5: 45944 | D5: 45947 | E5: 23 - 25 October 2025
B6: FHA-HoReCa | C6: 45950 | D6: 45953
B7: FinTech 2025 | C7: 45972 | D7: 45974
B8: Christmas Day | C8: 46015 | D8: 46016
B9: Year End | C9: 46021 | D9: 46023
B10: Year End | C10: 46022 | D10: 46022
B11: Singapore Airshow 2026 | C11: 46056 | D11: 46059 | E11: 3 - 6 Feb 2026
B12: Chinese New Year | C12: 46069 | D12: 46077 | E12: 16 - 24 Feb 2026
B13: Food & Hotel Beverage
B14: CommunicAsia
B15: National Day
B16: Singapore Formula One
B17: Golden week
B18: Christmas Day | C18: 46380 | D18: 46381
B19: Year End | C19: 46386 | D19: 46388
B20: Year End | C20: 46387 | D20: 46022

Sheet 호텔
B1: 하나등급 | C1: ReMark | D1: 위치 | E1: 영문 호텔명 | F1: 한글 호텔명 | G1: 룸 카테고리(SQM) | H1: 조식 | I1: 닷컴 | J1: 월 | K1: 화 | L1: 수 | M1: 목 | N1: 금 | O1: 토 | P1: 일 | Q1: 엑스트라 | R1: 조식(A) | S1: 조식(C) | T1: 전체룸 | U1: 트윈룸 | V1: 얼랏먼트
A2: 전보미 | B2: 3성 | C2: 인센티브 저가 호텔 | D2: 노베나 | E2: IBIS Novena | F2: 이비스 노베나 | G2: Standard (18sqm) | H2: 포함 | I2: 192343 | J2: 155 | Q2: X | R2: 24.95 | S2: 10 | T2: 241 | U2: 74
E3: IBIS Novena | F3: 이비스 노베나 | G3: Standard 8방이상 | H3: 포함 | I3: 192343 | J3: 145 | Q3: X
E4: IBIS Novena 7월~8월 | F4: 이비스 노베나 | G4: Standard | H4: 포함 | I4: 192343 | J4: 175 | Q4: X
E5: IBIS Novena | F5: 이비스 노베나 | G5: Triple & Family(20sqm) | H5: 포함 | I5: =I3+75000 -> 267343 | J5: 215 | Q5: X
A6: 함소연 | B6: 3.5성 | C6: 인센티브 트윈 게런티 FIT 추천 | D6: 무스타파 | E6: Hotel Boss | F6: 호텔 보스 | G6: Superior(14sqm) | H6: 포함 | I6: 154976 | J6: 173 | Q6: 93 | R6: 13 | S6: 13 | T6: 1500 | U6: 428
E7: Hotel Boss | F7: 호텔 보스 | G7: Superior(14sqm) 트윈 게런티 | H7: 포함 | I7: 154976 | J7: 185
E8: Hotel Boss | F8: 호텔 보스 | G8: premier(17sqm) | H8: 포함 | I8: 177552 | J8: 189
A9: 함소연 | B9: 4성 | C9: 인센티브 트윈 게런티 | D9: 무스타파 | E9: V Hotel Lavender | F9: V 호텔 라벤더 | G9: Superior(14sqm) | H9: 포함 | I9: 164245 | J9: 173 | Q9: 93 | R9: 13 | S9: 13 | T9: 888 | U9: 261
E10: V Hotel Lavender | F10: V 호텔 라벤더 | G10: Superior(14sqm) 트윈 게런티 | H10: 포함 | I10: 164245 | J10: 185
E11: V Hotel Lavender | F11: V 호텔 라벤더 | G11: premier(16sqm) | H11: 포함 | I11: 187233 | J11: 189
A12: 함소연 | B12: 3.5성 | C12: FIT 추천 | D12: 부기스 | E12: V Hotel Bencoolen | F12: V 호텔 벤쿨린 | G12: Superior(14sqm) | H12: 포함 | I12: 164065 | J12: 169 | Q12: X | R12: 13 | S12: 13 | T12: 272
E13: V Hotel Bencoolen | F13: V 호텔 벤쿨린 | G13: premier(16sqm) | H13: 포함 | I13: 184406 | J13: 189 | Q13: X
A14: 함소연 | B14: 3.5성 | C14: FIT 추천 | D14: 부기스 | E14: Hotel Mi Bencoolen | F14: 호텔 MI 벤클론 | G14: Superior(14sqm) | H14: 포함 | I14: 170614 | J14: 177 | Q14: X | R14: 13 | S14: 13 | T14: 342
E15: Hotel Mi Bencoolen | F15: 호텔 MI 벤클론 | G15: premier(17sqm) | H15: 포함 | I15: 199364 | J15: 197 | Q15: X
A16: 함소연 | B16: 3.5성 | C16: FIT 추천 | D16: 로처 | E16: Hotel Mi Rochor | F16: 호텔 MI 로초르 | G16: Superior(15sqm) | H16: 포함 | I16: 156808 | J16: 177 | Q16: X | R16: 13 | S16: 13 | T16: 530
E17: Hotel Mi Rochor | F17: 호텔 MI 로초르 | G17: premier(17sqm) | H17: 포함 | I17: 186599 | J17: 197 | Q17: X
B18: 3.5성 | C18: FIT 추천 | D18: 카통 | E18: Holiday Inn Express Katong | F18: 홀리데이인 익스프레스 카통 | G18: Standardr(19sqm) | H18: 포함 | I18: 217947 | J18: 200 | Q18: X | T18: 451
E19: Holiday Inn Express Katong | F19: 홀리데이인 익스프레스 카통 | G19: Standardr(19sqm) 8방이상 | H19: 포함 | I19: 217947 | J19: 180 | Q19: X
A20: 함소연 | B20: 3성 | C20: 인센티브 트윈 게런티 | D20: 벤쿨렌 | E20: IBIS on Bencoolen | F20: 이비스 벤쿨렌 | G20: Standard (18sqm) | H20: 포함 | I20: 210603 | J20: 175 | Q20: X | R20: 25 | S20: 12.5 | T20: 534 | U20: 124
E21: IBIS on Bencoolen | F21: 이비스 벤쿨렌 | G21: Superior (18sqm) | H21: 포함 | I21: 223226 | J21: 185 | Q21: X
E22: IBIS on Bencoolen 7월-8월 | F22: 이비스 벤쿨렌 | G22: Standard(18sqm) | H22: 포함 | I22: 210603 | J22: 195 | Q22: X
E23: IBIS on Bencoolen 7월-8월 | F23: 이비스 벤쿨렌 | G23: Superior(18sqm) | H23: 포함 | I23: 223226 | J23: 205 | Q23: X
A25: 정다혜 | B25: 4성 | C25: 인센티브 저가 호텔 | D25: 겔랑 | E25: MERCURE TYRWHITT | F25: 머큐어 티히트 | G25: Classic(15sqm) | H25: 포함 | I25: 205719 | J25: 200 | Q25: X | T25: 270 | U25: 104
E26: MERCURE TYRWHITT | F26: 머큐어 티히트 | G26: Classic (15sqm) 8방이상 | H26: 포함 | I26: 205719 | J26: 170 | Q26: X
A27: 전보미 | B27: 4성 | C27: FIT 추천 | D27: 부기스 | E27: Hotel Royal@Queens | F27: 로얄 앳 퀸즈 | G27: Executive room | H27: 포함 | I27: 196187 | J27: 200 | Q27: 65 | R27: 24.94 | S27: 17 | T27: 236 | U27: 65
A28: 전보미 | B28: 4성 | C28: 세이버 4성 학단 중심 | D28: 부킷 메라 | E28: Faber Park | F28: 페버 파크 | G28: Superior (15sqm) | H28: 포함 | I28: 214253 | J28: 200 | Q28: 100 | T28: 194 | U28: 112
E29: Faber Park | F29: 페버 파크 | G29: Deluxe (18sqm) | H29: 포함 | J29: 250 | Q29: 100
E30: Faber Park ~ 6월 | F30: 페버 파크 | G30: Superior (15sqm) | H30: 포함 | J30: 180 | Q30: 100
E31: Faber Park 7월~8월 | F31: 페버 파크 | G31: Superior (15sqm) | H31: 포함 | I31: 214253 | J31: 200 | Q31: 100
A32: 김현지 | B32: 4성 | C32: 패키지 서브 인센티브 서브 | D32: 차이나타운 | E32: Doresett | F32: 도르셋 | G32: Dorsett | H32: 포함 | I32: 197080 | J32: 270 | N32: 240 | Q32: X | T32: 285 | U32: 91
E33: Doresett | F33: 도르셋 | G33: Deluxe | H33: 포함 | I33: 250532 | J33: 300 | N33: 270 | Q33: 110
E34: Doresett ~6월 | F34: 도르셋 | G34: Dorsett (10방이상) | H34: 포함 | J34: 180 | Q34: 120
E35: Doresett ~ 6월 | F35: 도르셋 | G35: Deluxe (10방이상) | H35: 포함 | J35: 210 | Q35: 90
A36: 전보미 | B36: 4성 | C36: 패키지 서브 | D36: 갤랑 | E36: Hotel Traveltine | F36: 트레버틴 호텔 | G36: Superior | H36: 포함 | I36: 217430 | J36: 230 | T36: 300
E37: Hotel Traveltine | F37: 트레버틴 호텔 | G37: Superior 8방이상 | H37: 포함 | I37: 217430 | J37: 190
E38: Hotel Traveltine | F38: 트레버틴 호텔 | G38: Deluxe | H38: 포함 | I38: 234969 | J38: 260
A39: 김자명 | B39: 4성 | C39: 패키지 서브 FIT 추천 | D39: 오차드 | E39: Citadines Conneting | F39: 시타딘스 커넥팅 | G39: Standard (내측창문) | H39: 포함 | J39: 190
E40: Citadines Conneting | F40: 시타딘스 커넥팅 | G40: Deluxe (18sqm) | H40: 포함 | J40: 200
A41: 김현지 | B41: 4성 | C41: 인센티브 메인 FIT 추천 | D41: 탄중파가 | E41: ORCHID HOTEL | F41: 오키드 호텔 | G41: Deluxe(32sqm) | H41: 포함 | I41: 355465 | J41: 200 | Q41: 100 | T41: 226 | U41: 70
...

Sheet 호텔 (2)
A1: 한글 호텔명 | B1: 영문 호텔명 | C1: 등급 | D1: 룸 카테고리(SQM) | E1: 조식 | F1: 기간 시작일 | G1: 기간 종료일 | H1: 월 | I1: 화 | J1: 수 | K1: 목 | L1: 금 | M1: 토 | N1: 일 | O1: 엑스트라 | P1: 조식(A) | Q1: 조식(C) | R1: 금액 | S1: 엑스트라베드 | T1: 얼랏먼트 | U1: 위치 | V1: ReMark
A2: 이비스 노베나 | B2: IBIS Novena | C2: 3성 | D2: Standard (18sqm) | E2: 포함 | F2: 45658 | G2: 45838 | H2: 155 | O2: X | P2: 24.95 | Q2: 10 | R2: 241 | S2: 74 | U2: 노베나 | V2: 인센티브 저가 호텔
A3: 이비스 노베나 | B3: IBIS Novena | D3: Standard 8방이상 | E3: 포함 | F3: 45658 | G3: 45838 | H3: 145 | O3: X
A4: 이비스 노베나 | B4: IBIS Novena 7월~8월 | D4: Standard | E4: 포함 | F4: 45839 | G4: 45900 | H4: 175 | O4: X
A5: 이비스 노베나 | B5: IBIS Novena | D5: Standard (18sqm) | E5: 포함 | F5: 45901 | G5: 46022 | H5: 155 | O5: X
A6: 이비스 노베나 | B6: IBIS Novena | D6: Standard 8방이상 | E6: 포함 | F6: 45901 | G6: 46022 | H6: 145 | O6: X
A7: 이비스 노베나 | B7: IBIS Novena | D7: Triple & Family(20sqm) | E7: 포함 | F7: 45658 | G7: 46022 | H7: 215 | O7: X
A8: 호텔 보스 | B8: Hotel Boss | C8: 3.5성 | D8: Superior(14sqm) | E8: 포함 | F8: 45658 | G8: 46022 | H8: 173 | O8: 93 | P8: 13 | Q8: 13 | R8: 1500 | S8: 428 | U8: 무스타파 | V8: 인센티브 트윈 게런티 FIT 추천
A9: 호텔 보스 | B9: Hotel Boss | D9: Superior(14sqm) 트윈 게런티 | E9: 포함 | F9: 45658 | G9: 46022 | H9: 185
A10: 호텔 보스 | B10: Hotel Boss | D10: premier(17sqm) | E10: 포함 | F10: 45658 | G10: 46022 | H10: 189
A11: V 호텔 라벤더 | B11: V Hotel Lavender | C11: 4성 | D11: Superior(14sqm) | E11: 포함 | F11: 45658 | G11: 46022 | H11: 173 | O11: 93 | P11: 13 | Q11: 13 | R11: 888 | S11: 261 | U11: 무스타파 | V11: 인센티브 트윈 게런티
A12: V 호텔 라벤더 | B12: V Hotel Lavender | D12: Superior(14sqm) 트윈 게런티 | E12: 포함 | F12: 45658 | G12: 46022 | H12: 185
A13: V 호텔 라벤더 | B13: V Hotel Lavender | D13: premier(16sqm) | E13: 포함 | F13: 45658 | G13: 46022 | H13: 189
A14: V 호텔 벤쿨린 | B14: V Hotel Bencoolen | C14: 3.5성 | D14: Superior(14sqm) | E14: 포함 | F14: 45658 | G14: 46022 | H14: 169 | O14: X | P14: 13 | Q14: 13 | R14: 272 | U14: 부기스 | V14: FIT 추천
A15: V 호텔 벤쿨린 | B15: V Hotel Bencoolen | D15: premier(16sqm) | E15: 포함 | F15: 45658 | G15: 46022 | H15: 189 | O15: X
A16: 호텔 MI 벤클론 | B16: Hotel Mi Bencoolen | C16: 3.5성 | D16: Superior(14sqm) | E16: 포함 | F16: 45658 | G16: 46022 | H16: 177 | O16: X | P16: 13 | Q16: 13 | R16: 342 | U16: 부기스 | V16: 패키지 메인
A17: 호텔 MI 벤클론 | B17: Hotel Mi Bencoolen | D17: premier(17sqm) | E17: 포함 | F17: 45658 | G17: 46022 | H17: 197 | O17: X
A18: 호텔 MI 로초르 | B18: Hotel Mi Rochor | C18: 3.5성 | D18: Superior(15sqm) | E18: 포함 | F18: 45658 | G18: 46022 | H18: 177 | O18: X | P18: 13 | Q18: 13 | R18: 530 | U18: 로처 | V18: 패키지 서브 인센티브 서브
A19: 호텔 MI 로초르 | B19: Hotel Mi Rochor | D19: premier(17sqm) | E19: 포함 | F19: 45658 | G19: 46022 | H19: 197 | O19: X
A20: 홀리데이인 익스프레스 카통 | B20: Holiday Inn Express Katong | C20: 3.5성 | D20: Standardr(19sqm) | E20: 포함 | F20: 45658 | G20: 46022 | H20: 200 | O20: X | R20: 451 | U20: 카통 | V20: FIT 추천
A21: 홀리데이인 익스프레스 카통 | B21: Holiday Inn Express Katong | D21: Standardr(19sqm) 8방이상 | E21: 포함 | F21: 45658 | G21: 46022 | H21: 180 | O21: X
A22: M 호텔 시티 센터 | B22: M Hotel City Centre | C22: 4.5성 | D22: Deluxe (32sqm) | E22: 포함 | F22: 45658 | G22: 46022 | H22: 310 | I22: 310 | J22: 310 | K22: 310 | L22: 280 | M22: 280 | N22: 280 | O22: 110 | P22: 30 | Q22: 15 | R22: 415 | S22: 120 | U22: 탄중파가 | V22: 패키지 메인 인센티브 메인 => 월 400방 게런티
A23: M 호텔 시티 센터 | B23: M Hotel City Centre | D23: Premier (37sqm) | E23: 포함 | F23: 45658 | G23: 46022 | H23: 340 | I23: 340 | J23: 340 | K23: 340 | L23: 305 | M23: 305 | N23: 305 | O23: 110
A24: M 호텔 시티 센터 | B24: M Hotel City Centre (10방얼랏) | D24: Deluxe (32sqm) | E24: 포함 | F24: 45658 | G24: 46022 | H24: 210 | O24: 110 | T24: 10
A25: M 호텔 시티 센터 | B25: M Hotel City Centre (10방얼랏) | D25: Premier (37sqm) | E25: 포함 | F25: 45658 | G25: 46022 | H25: 240 | O25: 110 | T25: 10
A26: 호텔 젠 탕린 | B26: Hotel Jen Tanglin | C26: 4성 | D26: Superior (25sqm) | E26: 포함 | F26: 45658 | G26: 46022 | H26: 255 | O26: 90 | R26: 565 | S26: 110 | U26: 오차드 | V26: 패키지 메인 FIT 추천
A27: 호텔 젠 탕린 | B27: Hotel Jen Tanglin | D27: Deluxe (25sqm) | E27: 포함 | F27: 45658 | G27: 46022 | H27: 275 | O27: 90 | T27: 5
A28: 오아시아 다운타운 | B28: Oasia Downtown | C28: 4성 | D28: Superior(23sqm) | E28: 포함 | F28: 45658 | G28: 46022 | H28: 275 | O28: X | R28: 314 | U28: 탄중파가 | V28: FIT 추천
A29: 오아시아 다운타운 | B29: Oasia Downtown | D29: Deluxe(23sqm) | E29: 포함 | F29: 45658 | G29: 46022 | H29: 295 | O29: X
A31: 아마라 싱가포르 ( ~7/27) | B31: AMARA SINGAPORE | C31: 5성 | D31: Deluxe (32sqm) | E31: 포함 | H31: 210 | O31: 100 | P31: 36 | Q31: 18 | R31: 387 | S31: 100 | U31: 탄중파가 | V31: 전략적 운영
A32: 아마라 싱가포르 ( 8월 ~ ) | B32: AMARA SINGAPORE | D32: Deluxe (32sqm) | E32: 포함 | H32: 미 확정 220 ~ 230 | O32: 120
A33: 오차드 호텔 | B33: ORCHARD HOTEL | C33: 5성 | D33: Grand Deluxe | E33: 포함 | H33: 325 | I33: 325 | J33: 325 | K33: 325 | L33: 300 | M33: 300 | N33: 300 | R33: 656 | U33: 오차드 | V33: 패키지 메인 인센티브 추천 FIT 추천 =>월 720방 게런티
A34: 오차드 호텔 | B34: ORCHARD HOTEL | D34: Premier | E34: 포함 | H34: 355 | I34: 355 | J34: 355 | K34: 355 | L34: 330 | M34: 330 | N34: 330 | O34: 110
A35: 오차드 호텔 | B35: ORCHARD HOTEL (24방 얼랏) | D35: Garden Deluxe | E35: 포함 | H35: 240 | O35: 110 | T35: 24
A36: 오차드 호텔 | B36: 12월까지 | D36: Premier | E36: 포함 | H36: 325 | I36: 325 | J36: 325 | K36: 325 | L36: 300 | M36: 300 | N36: 300
A37: 그랜드 콥튼 워터프론트 | B37: Grand Copthorne Waterfront | C37: 5성 | D37: Grand Delex (26sqm) | E37: 포함 | H37: 335 | O37: 110 | P37: 30 | Q37: 18 | R37: 438 | S37: 106 | U37: 부킷 메라 | V37: 5성 프로모션
A38: 그랜드 콥튼 워터프론트 | B38: Grand Copthorne Waterfront | D38: Premier (32sqm) | E38: 포함 | H38: 365 | O38: 110
A39: 그랜드 콥튼 워터프론트 | B39: Grand Copthorne Waterfront | D39: Grand Delex (26sqm) | E39: 포함 | H39: 270 | O39: 110
A40: 그랜드 콥튼 워터프론트 | B40: 4월~6월 프로모션 | D40: Premier (32sqm) | E40: 포함 | H40: 300 | O40: 110
A41: 그랜드 파크 시티홀 | B41: Grand Park City hall | C41: 5성 | D41: Deluxe Room | E41: 포함 | H41: 310 | O41: 110 | P41: 30 | Q41: 20 | R41: 343 | S41: 103 | U41: 다운타운 | V41: FIT 추천
...

Sheet 일정
E1: 검증요금 | G1: 워킹 요금 | I1: 참고사항
A2: 구분 | B2: 영어명칭 | C2: 한글명칭 | E2: 성인요금 | F2: 아동요금
A3: 테마파크/워터파크 | B3: Universal Studios Singapore | C3: 유니버셜 스튜디오 싱가포르 | E3: 75.3 | F3: 59.3 | G3: 83 | H3: 62
A4: 테마파크/워터파크 | B4: USS Express Single/Unlimited (Regular) | C4: USS 익스프레스 싱글(노멀시즌) | E4: 85 | G4: 100 | H4: 100 | I4: 6월까지 EXPRESS 중단됨
A5: 테마파크/워터파크 | B5: USS Express Single/Unlimited (Peak) | C5: USS 익스프레스 싱글(피크시즌) | E5: 111 | G5: 110 | H5: 110
A6: 테마파크/워터파크 | B6: Admission + Express Pass (Single) - Super Peak Festive | C6: USS 익스프레스 싱글 (피크시즌) | E6: 196 | G6: 205 | H6: 205
A7: 체험/액티비티 | B7: Harry Potter: Visions of Magic | C7: 헤리포터 마법의 비젼 | E7: 49 | F7: 39 | G7: 69 | H7: 59
A8: 테마파크/워터파크 | B8: Adventure Cove Waterpark | C8: 어드벤처 코브 원터 파크 | E8: 35.3 | F8: 28.3 | G8: 40 | H8: 32
A9: 동물원/아쿠아리움 | B9: S.E.A. Aquarium | C9: S.E.A. 아쿠아리움 | E9: 41.3 | F9: 31.3 | G9: 44 | H9: 33
A10: 전망대/케이블카 | B10: Singapore Cable Car - Sky pass | C10: 센토사 케이블카 2라인 | E10: 22 | F10: 18 | G10: 35 | H10: 25 | I10: 2024년 5월부로 요금 인상
A11: 전망대/케이블카 | B11: Singapore Cable Car - Mount Faber Line | C11: 센토사 케이블카 1라인(마운틴페이버) | E11: 20 | F11: 15 | G11: 33 | H11: 22
A12: 어트랙션/티켓 | B12: SkyHelix Sentosa | C12: 스카이헬릭스 센토사 | E12: 13.5 | F12: 11 | G12: 20 | H12: 17
A13: 어트랙션/티켓 | B13: Wings of Time ( 7:40, Open / 8:40 ) | C13: 윙스오브타임 7:40 오픈 , 8/40분 입장 | E13: 11 | G13: 19 | H13: 19 | I13: 8시40분 9 SGD
A14: 어트랙션/티켓 | B14: Wings of Time ( 7:40, Open / 8:40 ) VIP | C14: 윙스오브타임 7:40 오픈 , 8/40분 입장 | E14: 19 | G14: 28 | H14: 28
A15: 어트랙션/티켓 | B15: Wings of Time - 7.40PM + Good Old Days Buffet | C15: 윙스오브타임 7:40 + 굳 올드데이스 뷔페 | E15: 26 | G15: 49
A16: 어트랙션/티켓 | B16: Wings of Time - 8.40PM + Good Old Days Buffet | C16: 윙스오브타임 8:40 + 굳 올드데이스 뷔페 | E16: 24 | G16: 49
A17: 어트랙션/티켓 | B17: Wings of Time Open+Cable Car(1 Round)+Good Old Days Buffet | C17: 윙스오브타임 오픈+케이블카1회왕복+뷔페 | E17: 43 | F17: 39 | G17: 84 | H17: 74
A18: 어트랙션/티켓 | B18: Madame Tussauds Sentosa | C18: 마담투소 (Marvel 4D, Digphoto 포함) | E18: 26.8 | G18: 48
A19: 어트랙션/티켓 | B19: Madame Tussauds Sentosa | C19: 마담투소 (Marvel 4D 불포함) | E19: 22.8 | G19: 42
A20: 어트랙션/티켓 | B20: Skyline Luge Singapore( 3 rounds) | C20: 센토사 스카이라인 루지&스카이라이드(3회) | E20: 31.5 | G20: 35
A21: 어트랙션/티켓 | B21: Big Bus Singapore | C21: 2층 버스 (빅버스) | E21: 17 | F21: 17 | G21: 59 | H21: 49
A22: 어트랙션/티켓 | B22: Singapore DUCKtours | C22: 싱가포르 덕투어 | E22: 33.75 | F22: 26 | G22: 45 | H22: 35
A23: 어트랙션/티켓 | B23: Funvee + Duck | C23: 2층버스 + 빅버스 | E23: 49.3 | F23: 35.3 | G23: 70 | H23: 50
A24: 어트랙션/티켓 | B24: Funvee Bus | C24: 2층 버스 (펀비버스) - 2시간 1일 | E24: 21.3 | F24: 14.3 | G24: 30 | H24: 20
A25: 어트랙션/티켓 | B25: Gardens by the Bay - Cloud Forest+Supertree Observatory | C25: 가든스바이더베이 클라우드 + 슈퍼트리전망대 | E25: 18.3 | F25: 10.3 | G25: 34 | H25: 21
A26: 어트랙션/티켓 | B26: Gardens by the Bay Flower Dome+Supertree Observatory | C26: 가든스바이더베이 플라워돔+슈퍼트리 전망대 | E26: 18.2 | F26: 10.2 | G26: 32 | H26: 18 | I26: 5/29~3/31 쥬랴기
A27: 어트랙션/티켓 | B27: Gardens by the Bay - Flower Dome+Cloud Forest | C27: 가든스바이더베이 2돔 ( 쥬랴기 ) | E27: 28.3 | F27: 20.3
A28: 어트랙션/티켓 | B28: National Orchid Gardens | C28: 내셔널 오키드 가든 | E28: 7.5 | F28: 7.5 | G28: 15 | H28: 15
A29: 어트랙션/티켓 | B29: Singapore Flyer | C29: 싱가포르 플라이어 | E29: 36.3 | F29: 22.8 | G29: 40 | H29: 25 | I29: 1달 점검으로 미운영 예정, 시부 에어 요금체크
A30: 체험/액티비티 | B30: Singapore River Cruise | C30: 리버크루즈 (리버보트) | E30: 15 | F30: 15 | G30: 28 | H30: 18
A31: 체험/액티비티 | B31: National University of Singapore Tour | C31: 싱가포르 국립대학(NUS) 재학생 투어 (차량당) | E31: 200 | F31: 200
A32: 박물관/갤러리 | B32: National Museum of Singapore | C32: 싱가포르 국립 박물관 | E32: 13.3 | F32: 10.3 | G32: 15 | H32: 11
A33: 박물관/갤러리 | B33: National Gallery | C33: 싱가포르 내셔널 갤러리 | E33: 10.3 | F33: 10.3 | G33: 20 | H33: 14
A34: 박물관/갤러리 | B34: Science Centre Singapore | C34: 싱가포르 사이언스 센터 (옴니극장 포함) | E34: 8.3 | F34: 5.8 | G34: 12 | H34: 8
A35: 전망대/케이블카 | B35: SkyPark Observation Deck (peak) | C35: 마리나베이 샌즈 스카이파크 전망대 | E35: 34.3 | F35: 29.3 | G35: 36 | H35: 32
A36: 전망대/케이블카 | B36: SkyPark Observation Deck (non Peak) | C36: 마리나베이 샌즈 스카이파크 전망대 | E36: 30.3 | F36: 29.3 | G36: 32 | H36: 28 | I36: 시부 에어 요금 체크
A37: 동물원/아쿠아리움 | B37: Night Safari | C37: 나이트 사파리 | E37: 42.84 | F37: 29.84 | G37: 50.4 | H37: 35.1 | I37: 2024년 4월 1일 인상 요금 반영
A38: 동물원/아쿠아리움 | B38: River Wonders | C38: 리버원더스 (리버사파리) | E38: 23.5 | F38: =15.5+5 -> 20.5 | G38: 43 | H38: 31 | K38: 48++
A39: 동물원/아쿠아리움 | B39: River Wonders (+Boat) | C39: 리버원더스 (리버사파리, 보트 포함) | E39: =E38+5 -> 28.5 | F39: =F38+5 -> 25.5 | G39: =G38+5 -> 48 | H39: =H38+5 -> 36 | K39: 20
A40: 동물원/아쿠아리움 | B40: Bird Paradise | C40: 버드 파라다이스 | E40: 24.5 | F40: 24.5 | G40: 49 | H40: 34 | J40: 54.3 | K40: =J40-E40 -> 29.8 | L40: =E38/2 -> 11.75
...

Sheet 식사
E1: 검증요금
A2: 종류 | B2: 식당명 | C2: 구분 | D2: 주요 메뉴 | E2: 성인요금 | F2: 아동요금 | G2: 최대인원
A3: 한식 | B3: (석식) SBCD 코리안 두부 하우스 | C3: 일반식 | D3: 순두부 돼지고기볶음 세트 | E3: 25 | F3: 25
A4: 한식 | B4: SBCD두부하우스 | C4: 특식 | D4: 순두부 LA갈비 세트 | E4: 40 | F4: 40
A5: 한식 | B5: 고려정 | C5: 일반식 | D5: 김치/된장 찌개 + 제육볶음 | E5: 16 | F5: 16
A6: 한식 | B6: 고려정 | C6: 특식 | D6: 김치찌개 제육복음 김치전 세트 | E6: 25 | F6: 25
A7: 한식 | B7: 고로고로 | C7: 일반식 | D7: 스팀보트 | E7: 18 | F7: 18
A8: 중식 | B8: 동방미식(점심만) | C8: 일반식 | D8: 볶음밥 쿼바로우 세트 | E8: 18 | F8: 18
A9: 현지식 | B9: 레드하우스 | C9: 특식 | D9: 칠리크랩 세트(저녁 또는 주말/휴일) | E9: 65 | F9: 65
A10: 현지식 | B10: (중식) 칠리크랩- 레드하우스_주중 | C10: 특식 | D10: 칠리크랩 세트(주중 점심) | E10: 45 | F10: 45
A11: 현지식 | B11: 점보레스토랑(이스트코스트) | C11: 특식 | D11: 칠리크랩 세트 | E11: 60 | F11: 60
A12: 현지식 | B12: 블랑코 새우국수 | C12: 일반식 | D12: 새우국수(점심) | E12: 15 | F12: 15
A13: 현지식 | B13: 썸딤섬 | C13: 일반식 | D13: 딤섬 세트 - 일반 | E13: 20
A14: 현지식 | B14: 썸딤섬 | C14: 일반식 | D14: 딤섬 세트 - 스패셜 | E14: 25
A15: 한식 | B15: 더고기집 | C15: 일반식 | D15: 부대찌게 불고기 세트 | E15: 18 | F15: 18
A16: 한식 | B16: 더고기집 | C16: 특식 | D16: 삼겹살 무제한(저녁) | E16: 30 | F16: 30 | O16: frnr
A17: 한식 | B17: I am Kim | D17: 고기뷔페 (저녁) | E17: 21.9 | F17: 21.9
A18: 한식 | B18: I am Kim | D18: 고기뷔페 (점심) | E18: 15.9 | F18: 15.9
A19: 현지식 | B19: 송파바쿠테 | C19: 일반식 | D19: 바쿠테 - 점심 | E19: 17 | F19: 17
A20: 현지식 | B20: 송파바쿠테 | C20: 특식 | D20: 바쿠테 - 저녁 | E20: 20 | F20: 20
A21: 현지식 | B21: 스트레잇 차이니즈 | C21: 일반식 | D21: 페라나칸식 (9명 이상) | E21: 18 | F21: 18
A22: 현지식 | B22: 스트레잇 차이니즈 | C22: 일반식 | D22: 페라나칸식 (8명 이하) | E22: 22 | F22: 22
A23: 현지식 | B23: 얌차 | C23: 특식 | D23: 딤섬 세트 (주중, 점심) | E23: 28 | F23: 28
A24: 현지식 | B24: 얌차 | C24: 특식 | D24: 딤섬 세트 (주말, 저녁) | E24: 32 | F24: 32
A25: 현지식 | B25: 스트레잇 차이니즈 (에스플레이드) | C25: 일반식 | D25: 딤섬 | E25: 22 | F25: 22
A26: 현지식 | B26: 지엔 | C26: 특식 | D26: 딤섬 세트 | E26: 22 | F26: 22
A27: 현지식 | B27: 지엔 | C27: 특식 | D27: 칠리크랩세트(10명 미만) | E27: 45 | F27: 45
A28: 현지식 | B28: 지엔 | C28: 특식 | D28: 칠리크랩세트 (10명이상) | E28: 35 | F28: 35
A29: 현지식 | B29: 코카 스팀보트 | C29: 특식 | D29: 스팀보트( 주중 점심) | E29: 47 | F29: 32
A30: 현지식 | B30: 코카 스팀보트 | C30: 특식 | D30: 스팀보트(주말 점심) | E30: 52 | F30: 34
... A33: 중식 | B33: 카야 토스트 세트 시식 | C33: 일반식 | D33: 카야토스트 세트(조식용) | E33: 10 | F33: 10
A34: 간식 | B34: 열대과일 | D34: 부기스시장 | E34: 5 | F34: 5
A35: 조식 | B35: 동물원 조식(09:~10:30) | C35: 특식 | D35: 만다이 동물원 뷔페 | E35: 35 | F35: 26
A36: 뷔페 | B36: (중식) 펭귄코브 레스토랑 | C36: 일반식 | E36: 20 | F36: 20
A37: 중식 | B37: 버드파라다이스 | C37: 특식 | D37: 크림손 3코스 런치 세트 | E37: 49 | F37: 49
A38: 석식 | B38: 센토사 올드굿데이즈 | C38: 특식 | D38: 로컬 뷔페 | E38: 20 | F38: 20
A39: 석식 | B39: 라우파사 | C39: 특식 | D39: 사테 세트 | E39: 20 | F39: 20
A40: 중식 | B40: 센토사 올드굿데이즈 | C40: 특식 | D40: 치킨라이스 | E40: 15 | F40: 20
A41: 뷔페 | B41: (석식) 아마라호텔_엘리멘트 뷔페 | C41: 일반식 | E41: 42 | F41: 42

Sheet 현지투어플러스
A1: home | E1: ='가이드&차량'!B1 -> 1100 | G1: 호텔 | H1: 트윈/더블 | I1: =C4/2 -> 2 | J1: 싱글 | K1: 0 | L1: 금액 | M1: 룸넘버 | N1: 소계 | O1: 합계 | V1: * 서차지기간 확인필수 | AC1: 주중 | AD1: 주말
B2: 마스터코드 | C2: 현지투어 플러스 | H2: =C5 -> 45732 | J2: =AB2 -> Amara Singapore | L2: =IF( (IF(WEEKDAY(H2, 2) <= 5, AC2, AD2) + IF(AND(H2 >= W3, H2 <= X3), Z3, 0) + IF(AND(H2 >= W4, H2 <= X4), Z4, 0) + IF(AND(H2 >= W5, H2 <= X5), Z5, 0) + IF(AND(H2 >= W6, H2 <= X6), Z6, 0) + IF(AND(H2 >= W7, H2 <= X7), Z7, 0) + IF(AND(H2 >= W8, H2 <= X8), Z8, 0) + IF(AND(H2 >= W9, H2 <= X9), Z9, 0) + IF(AND(H2 >= W10, H2 <= X10), Z10, 0)) < 1, "Surcharge Check", (IF(WEEKDAY(H2, 2) <= 5, AC2, AD2) + IF(AND(H2 >= W3, H2 <= X3), Z3, 0) + IF(AND(H2 >= W4, H2 <= X4), Z4, 0) + IF(AND(H2 >= W5, H2 <= X5), Z5, 0) + IF(AND(H2 >= W6, H2 <= X6), Z6, 0) + IF(AND(H2 >= W7, H2 <= X7), Z7, 0) + IF(AND(H2 >= W8, H2 <= X8), Z8, 0) + IF(AND(H2 >= W9, H2 <= X9), Z9, 0) + IF(AND(H2 >= W10, H2 <= X10), Z10, 0)) ) -> 230 | M2: =$I$1+$K$1 -> 2 | N2: =L2*M2 -> 460 | O2: =SUM(N2:N6) -> 1840 | Q2: 옵션 - 5개 | R2: -40 | S2: 쇼핑 - 4회 | T2: -30 | V2: EVENT | W2: 시작일 | X2: 마감일 | Y2: 실제 행사일 | AB2: Amara Singapore | AC2: 230 | AD2: 230
B3: 구분[여정] | H3: =H2+1 -> 45733 | J3: =J2 -> Amara Singapore | L3: =IF( (IF(WEEKDAY(H3, 2) <= 5, AC2, AD2) + IF(AND(H3 >= W3, H3 <= X3), Z3, 0) + IF(AND(H3 >= W4, H3 <= X4), Z4, 0) + IF(AND(H3 >= W5, H3 <= X5), Z5, 0) + IF(AND(H3 >= W6, H3 <= X6), Z6, 0) + IF(AND(H3 >= W7, H3 <= X7), Z7, 0) + IF(AND(H3 >= W8, H3 <= X8), Z8, 0) + IF(AND(H3 >= W9, H3 <= X9), Z9, 0) + IF(AND(H3 >= W10, H3 <= X10), Z10, 0)) < 1, "Surcharge Check", (IF(WEEKDAY(H3, 2) <= 5, AC2, AD2) + IF(AND(H3 >= W3, H3 <= X3), Z3, 0) + IF(AND(H3 >= W4, H3 <= X4), Z4, 0) + IF(AND(H3 >= W5, H3 <= X5), Z5, 0) + IF(AND(H3 >= W6, H3 <= X6), Z6, 0) + IF(AND(H3 >= W7, H3 <= X7), Z7, 0) + IF(AND(H3 >= W8, H3 <= X8), Z8, 0) + IF(AND(H3 >= W9, H3 <= X9), Z9, 0) + IF(AND(H3 >= W10, H3 <= X10), Z10, 0)) ) -> 230 | M3: =$I$1+$K$1 -> 2 | N3: =L3*M3 -> 460 | Q3: 옵션 - 4개 | R3: -30 | S3: 쇼핑 - 3회 | T3: -20 | V3: =서차지!B3 -> World Paralympic Swimming | W3: =서차지!C3 -> 45921 | X3: =서차지!D3 -> 45562 | Y3: =서차지!E3 -> 21 – 27 September 2025 | Z3: -2000
B4: 인원(손님) | C4: 4 | D4: 인원(FOC) | E4: 0 | H4: =H3+1 -> 45734 | J4: =J2 -> Amara Singapore | L4: =IF( (IF(WEEKDAY(H4, 2) <= 5, AC2, AD2) + IF(AND(H4 >= W3, H4 <= X3), Z3, 0) + IF(AND(H4 >= W4, H4 <= X4), Z4, 0) + IF(AND(H4 >= W5, H4 <= X5), Z5, 0) + IF(AND(H4 >= W6, H4 <= X6), Z6, 0) + IF(AND(H4 >= W7, H4 <= X7), Z7, 0) + IF(AND(H4 >= W8, H4 <= X8), Z8, 0) + IF(AND(H4 >= W9, H4 <= X9), Z9, 0) + IF(AND(H4 >= W10, H4 <= X10), Z10, 0)) < 1, "Surcharge Check", (IF(WEEKDAY(H4, 2) <= 5, AC2, AD2) + IF(AND(H4 >= W3, H4 <= X3), Z3, 0) + IF(AND(H4 >= W4, H4 <= X4), Z4, 0) + IF(AND(H4 >= W5, H4 <= X5), Z5, 0) + IF(AND(H4 >= W6, H4 <= X6), Z6, 0) + IF(AND(H4 >= W7, H4 <= X7), Z7, 0) + IF(AND(H4 >= W8, H4 <= X8), Z8, 0) + IF(AND(H4 >= W9, H4 <= X9), Z9, 0) + IF(AND(H4 >= W10, H4 <= X10), Z10, 0)) ) -> 230 | M4: =$I$1+$K$1 -> 2 | N4: =L4*M4 -> 460 | Q4: 옵션 - 3개 | R4: -20 | S4: 쇼핑 - 2회 | T4: -10 | V4: =서차지!B4 -> Singapore Formula One (F1) | W4: =서차지!C4 -> 45932 | X4: =서차지!D4 -> 45935 | Y4: =서차지!E4 -> 02 Oct - 05 Oct, 2025 | Z4: -2000 | AB4: Momentus | AC4: 190 | AD4: 180
B5: 도착날짜 | C5: 45732 | D5: 3 | E5: =C5+D5 -> 45735 | H5: =H4+1 -> 45735 | J5: =J2 -> Amara Singapore | L5: =IF( (IF(WEEKDAY(H5, 2) <= 5, AC2, AD2) + IF(AND(H5 >= W3, H5 <= X3), Z3, 0) + IF(AND(H5 >= W4, H5 <= X4), Z4, 0) + IF(AND(H5 >= W5, H5 <= X5), Z5, 0) + IF(AND(H5 >= W6, H5 <= X6), Z6, 0) + IF(AND(H5 >= W7, H5 <= X7), Z7, 0) + IF(AND(H5 >= W8, H5 <= X8), Z8, 0) + IF(AND(H5 >= W9, H5 <= X9), Z9, 0) + IF(AND(H5 >= W10, H5 <= X10), Z10, 0)) < 1, "Surcharge Check", (IF(WEEKDAY(H5, 2) <= 5, AC2, AD2) + IF(AND(H5 >= W3, H5 <= X3), Z3, 0) + IF(AND(H5 >= W4, H5 <= X4), Z4, 0) + IF(AND(H5 >= W5, H5 <= X5), Z5, 0) + IF(AND(H5 >= W6, H5 <= X6), Z6, 0) + IF(AND(H5 >= W7, H5 <= X7), Z7, 0) + IF(AND(H5 >= W8, H5 <= X8), Z8, 0) + IF(AND(H5 >= W9, H5 <= X9), Z9, 0) + IF(AND(H5 >= W10, H5 <= X10), Z10, 0)) ) -> 230 | M5: =$I$1+$K$1 -> 2 | N5: =L5*M5 -> 460 | Q5: 옵션 - 2개 | R5: 0 | S5: 쇼핑 - 1회 | T5: 0 | V5: =서차지!B5 -> ITB Asia | W5: =서차지!C5 -> 45944 | X5: =서차지!D5 -> 45947 | Y5: =서차지!E5 -> 23 - 25 October 2025 | Z5: -2000 | AB5: Aloft Novena | AC5: 180 | AD5: 180
B6: 인당 지상비 (SGD) | C6: =(SUM(O10:O46)+O2)/C4+R5+T5 -> 1255.6 | D6: 인당 지상비 (원화) | E6: =C6*$E$1 -> 1381160 | Q6: 옵션 - 0개 | R6: 5 | S6: 쇼핑 - 0회 | T6: 5 | V6: =서차지!B6 -> FHA-HoReCa | W6: =서차지!C6 -> 45950 | X6: =서차지!D6 -> 45953 | Y6: =서차지!E6 -> 0 | Z6: -2000 | AB6: Mercure Stevens | AC6: 195 | AD6: 195
B7: 옵션 | C7: 0 | D7: 쇼핑 | E7: 0 | V7: =서차지!B7 -> FinTech 2025 | W7: =서차지!C7 -> 45972 | X7: =서차지!D7 -> 45974 | Y7: =서차지!E7 -> 0 | Z7: -2000 | AB7: M Hotel City Centre | AC7: 210 | AD7: 210
G8: 입장료(항공) | I8: 식사비 | K8: 차량 | M8: 가이드 | O8: 총합계 | V8: =서차지!B8 -> Christmas Day | W8: =서차지!C8 -> 46015 | X8: =서차지!D8 -> 46016 | Y8: =서차지!E8 -> 0 | Z8: -2000 | AB8: Concorde Hotel | AC8: 230 | AD8: 230
B9: SGD/WON | C9: =E1 -> 1100 | D9: SGD/MYR | E9: 3.5 | G9: 금액 | H9: 인원 | I9: 금액 | J9: 인원 | K9: 금액 | L9: 인원 | M9: 금액 | N9: 인원 | V9: =서차지!B9 -> Year End | W9: =서차지!C9 -> 46021 | X9: =서차지!D9 -> 46023 | Y9: =서차지!E9 -> 0 | Z9: -2000 | AB9: Oasia Novena | AC9: 225 | AD9: 225
B10: =TEXT(C5,"m월 d일 aaaa") -> 3월 16일 일요일 | C10: 인천출발 - 싱가포르 도착 | O10: =(G10*H10)+(I10*J10)+(K10*L10)+(M10*N10) -> 0 | V10: =서차지!B10 -> Year End | W10: =서차지!C10 -> 46022 | X10: =서차지!D10 -> 46022 | Y10: =서차지!E10 -> 0 | Z10: -2000 | AB10: Orchid Hotel | AC10: 220 | AD10: 220
C11: 공항 -> 싱가포르 호텔 개별 이동 | O11: =(G11*H11)+(I11*J11)+(K11*L11)+(M11*N11) -> 0 | V11: =서차지!B11 -> Singapore Airshow 2026 | W11: =서차지!C11 -> 46056 | X11: =서차지!D11 -> 46059 | Y11: =서차지!E11 -> 3 - 6 Feb 2026 | AB11: Amara Singapore | AC11: 230 | AD11: 230
C12: 싱가포르 호텔 투숙 | O12: =(G12*H12)+(I12*J12)+(K12*L12)+(M12*N12) -> 0 | V12: =서차지!B12 -> Chinese New Year | W12: =서차지!C12 -> 46069 | X12: =서차지!D12 -> 46077 | Y12: =서차지!E12 -> 16 - 24 Feb 2026 | AB12: Orchard Hotel | AC12: 240 | AD12: 240
B13: =TEXT(C5+1,"m월 d일 aaaa") -> 3월 17일 월요일 | C13: 호텔 조식 후 가이드 미팅 | K13: 150 | L13: 1 | M13: 360 | N13: 1 | O13: =(G13*H13)+(I13*J13)+(K13*L13)+(M13*N13) -> 510 | Q13: 차량/가이드 10시간 기준 | V13: =서차지!B13 -> Food & Hotel Beverage | W13: =서차지!C13 -> 0 | X13: =서차지!D13 -> 0 | Y13: =서차지!E13 -> 0 | AB13: Grand Copthorne | AC13: 240 | AD13: 240
C14: 리버원더스 | G14: =일정!E38 -> 23.5 | H14: =$C$4+$E$4 -> 4 | O14: =(G14*H14)+(I14*J14)+(K14*L14)+(M14*N14) -> 94 | V14: =서차지!B14 -> CommunicAsia | W14: =서차지!C14 -> 0 | X14: =서차지!D14 -> 0 | Y14: =서차지!E14 -> 0 | AB14: Mercure Tyrwhitt | AC14: 170 | AD14: 170
C15: (중식) 페라나카식 | I15: =식사!E21 -> 18 | J15: =$C$4+$E$4 -> 4 | O15: =(G15*H15)+(I15*J15)+(K15*L15)+(M15*N15) -> 72 | V15: =서차지!B15 -> National Day | W15: =서차지!C15 -> 0 | X15: =서차지!D15 -> 0 | Y15: =서차지!E15 -> 0 | AB15: Hotel Boss | AC15: 185 | AD15: 185
C16: 머라이언 공원+에스플라네이드 | O16: =(G16*H16)+(I16*J16)+(K16*L16)+(M16*N16) -> 0 | AB16: V Hotel Lavender | AC16: 185 | AD16: 185
C17: 가든스바이더베이(1돔+전망대) | G17: =일정!E26 -> 18.2 | H17: =$C$4+$E$4 -> 4 | O17: =(G17*H17)+(I17*J17)+(K17*L17)+(M17*N17) -> 72.8 | AB17: IbIs Novena | AC17: 155 | AD17: 155
C18: (석식) 오빠샤브- 스팀보트 +한식 뷔페 | I18: =식사!E7 -> 18 | J18: =$C$4+$E$4 -> 4 | O18: =(G18*H18)+(I18*J18)+(K18*L18)+(M18*N18) -> 72 | AB18: IbIs bencoolen | AC18: 185 | AD18: 185
C19: 리버보트 탑승 + 슈퍼트리쇼 | G19: =일정!E30 -> 15 | H19: =$C$4+$E$4 -> 4 | O19: =(G19*H19)+(I19*J19)+(K19*L19)+(M19*N19) -> 60 | AB19: Oasia Sentosa | AC19: 280 | AD19: 280
C20: 호텔 복귀 휴식 및 취침 | O20: =(G20*H20)+(I20*J20)+(K20*L20)+(M20*N20) -> 0 | AB20: Swissotel The stamford | AC20: 366 | AD20: 366
B21: =TEXT(C5+2,"m월 d일 aaaa") -> 3월 18일 화요일 | C21: 호텔 조식 후 가이드 미팅 | K21: 150 | L21: 1 | M21: 360 | N21: 1 | O21: =(G21*H21)+(I21*J21)+(K21*L21)+(M21*N21) -> 510 | Q21: 차량/가이드 10시간 기준
C22: USS 자유 관람 | G22: =일정!E3 -> 75.3 | H22: =$C$4+$E$4 -> 4 | O22: =(G22*H22)+(I22*J22)+(K22*L22)+(M22*N22) -> 301.2
C23: (중식) 자유식 20 SGD | I23: 20 | J23: =$C$4+$E$4 -> 4 | O23: =(G23*H23)+(I23*J23)+(K23*L23)+(M23*N23) -> 80
C24: (석식) 한식당 - 고기집(부대찌게+불고기세트) | I24: =식사!E15 -> 18 | J24: =$C$4+$E$4 -> 4 | O24: =(G24*H24)+(I24*J24)+(K24*L24)+(M24*N24) -> 72
C25: 호텔 수영장 | O25: =(G25*H25)+(I25*J25)+(K25*L25)+(M25*N25) -> 0
C26: 호텔 복귀 휴식 및 취침 | O26: =(G26*H26)+(I26*J26)+(K26*L26)+(M26*N26) -> 0
B27: =TEXT(C5+3,"m월 d일 aaaa") -> 3월 19일 수요일 | C27: 호텔 조식 후 가이드 미팅 | K27: 150 | L27: 1 | M27: 360 | N27: 1 | O27: =(G27*H27)+(I27*J27)+(K27*L27)+(M27*N27) -> 510 | Q27: 차량/가이드 12시간 기준
C28: 버드파라다이스 | G28: =일정!E40 -> 24.5 | H28: =$C$4+$E$4 -> 4 | O28: =(G28*H28)+(I28*J28)+(K28*L28)+(M28*N28) -> 98
C29: (중식) 팽귄코브 | I29: =식사!E36 -> 20 | J29: =$C$4+$E$4 -> 4 | O29: =(G29*H29)+(I29*J29)+(K29*L29)+(M29*N29) -> 80
C30: 싱가포르 사이언스 센터 | G30: =일정!E34 -> 8.3 | H30: =$C$4+$E$4 -> 4 | O30: =(G30*H30)+(I30*J30)+(K30*L30)+(M30*N30) -> 33.2
C31: 비보시티 | O31: =(G31*H31)+(I31*J31)+(K31*L31)+(M31*N31) -> 0
C32: (석식) 비보시티 자유식 | I32: 20 | J32: =$C$4+$E$4 -> 4 | O32: =(G32*H32)+(I32*J32)+(K32*L32)+(M32*N32) -> 80
C33: 호텔 수영장 | O33: =(G33*H33)+(I33*J33)+(K33*L33)+(M33*N33) -> 0
C34: 호텔 복귀 휴식 및 취침 | O34: =(G34*H34)+(I34*J34)+(K34*L34)+(M34*N34) -> 0
B35: =TEXT(C5+4,"m월 d일 aaaa") -> 3월 20일 목요일 | C35: 호텔 조식 후 체크아웃 | K35: 150 | L35: =L10 -> 0 | M35: 360 | N35: =N10 -> 0 | O35: =(G35*H35)+(I35*J35)+(K35*L35)+(M35*N35) -> 0 | Q35: 차량/가이드 12시간 기준
C36: (중식) 팽귄코브 | I36: =식사!E43 -> 0 | J36: =$C$4+$E$4 -> 4 | O36: =(G36*H36)+(I36*J36)+(K36*L36)+(M36*N36) -> 0
C37: 싱가포르 사이언스 센터 | G37: =일정!E41 -> 54.3 | H37: =$C$4+$E$4 -> 4 | O37: =(G37*H37)+(I37*J37)+(K37*L37)+(M37*N37) -> 217.2
C38: 비보시티 | O38: =(G38*H38)+(I38*J38)+(K38*L38)+(M38*N38) -> 0
C39: (석식) 비보시티 자유식 | I39: 20 | J39: =$C$4+$E$4 -> 4 | O39: =(G39*H39)+(I39*J39)+(K39*L39)+(M39*N39) -> 80
C40: 최종 방문지 -> 싱가포르 호텔 이동
...

Sheet 상품리스트
B2: 마스터코드 | C2: 상품명 | D2: 숙박지역 | K2: 항공편 | L2: 도착시간 | M2: 항공편 | N2: 출발시간
B3: 초등학교1 | C3: 싱가포르 4박 #USS #리버원더스 #리버보트 #버드파라다이스 #사이언스센터 | D3: 싱-싱-싱-싱
B4: 초등학교2 | C4: 싱가포르 3박 #USS #리버원더스 #스카이파크 #사이언스센터 | D4: 싱-싱-싱
B5: 중학교1 | C5: #USS #NUS투어 #윙스오브타임 #스카이파크 #리버보트 | D5: 싱-싱-싱
B6: 고등학교1 | C6: #USS #NUS투어 #윙스오브타임 #리버원더스 #리버보트 | D6: 싱-싱-싱
B7: 고등학교2 | C7: #USS #NUS투어 #무제한삼겹살 #리버원더스 #리버보트 | D7: 싱-싱-싱
B8: ASP210_OZA | C8: #4성호텔 #버드파라다이스+뷔페 #센토사루지 #마담투소 #리버원더스 #핵심관광지 #호텔디너뷔페 #NO쇼핑/NO팁 | D8: 싱-싱-싱 | E8: OZ751 | F8: 0.89583333 | H8: OZ752 | I8: 0.95138889
B9: ASP210_KEG | C9: #USS #핵심관광+센토사 #칠리크랩 #버드파라다이스 #윙스오브타임 #4성호텔 | D9: 싱-싱-싱 | E9: KE645 | F9: 0.98611111 | H9: KE646 | I9: 0.048611111
B10: ASP210_KED | C10: 스타가이드 #5성 아마라호텔 #버드파라다이스+뷔페 #센토사루지 #마담투소 #리버원더스 #핵심관광지 #호텔디너뷔페 | D10: 싱-싱-싱 | E10: KE645 | F10: 0.98611111 | H10: KE646 | I10: 0.048611111
B11: ASP210_SQD | C11: 스타가이드 #5성 아마라호텔 #버드파라다이스+뷔페 #센토사루지 #마담투소 #리버원더스 #핵심관광지 #호텔디너뷔페 | D11: 싱-싱-싱 | E11: SQ607 | F11: 0.59722222 | H11: SQ608 | I11: 0.0069444444
B12: ASP210_SQA | C12: 스타가이드 #버드파라다이스+뷔페 #센토사 루지 #마담투소 #리버원더스 #핵심관광지 #4성호텔 #NO쇼핑NO팁 | D12: 싱-싱-싱 | E12: SQ607 | F12: 0.60069444 | H12: SQ608 | I12: 0.0069444444
B13: ASP210_SQ4 | C13: 스타가이드 #5성 아마라호텔 #버드파라다이스+뷔페 #센토사루지 #마담투소 #리버원더스 #핵심관광지 #호텔디너뷔페 | D13: 싱-싱-싱 | E13: SQ601 | F13: 0.91666667 | H13: SQ612 | I13: 0.10069444
B14: ASP210_4박 | C14: 싱가포르 4박
B15: ASP211_TWG | C15: #전일관광 #리버원더스 #헤리티지도보투어 #핵심관광지 | D15: 싱-싱-싱 | E15: TW0171 | F15: 0.017361111 | H15: TW0172 | I15: 0.079861111
B16: ASP211_TWC | C16: #완전특가 #전일관광 #에메랄드힐 #센토사섬 #슈퍼트리쇼 #4성호텔 | D16: 싱-싱-싱 | E16: TW0163 | F16: 0.020833333 | H16: TW164 | I16: 0.083333333
B17: ASP211_KE3 | C17: #완전특가 #전일관광 #에메랄드힐 #센토사섬 #슈퍼트리쇼 #4성호텔 | D17: 싱-싱-싱 | E17: KE643 | F17: 0.82986111 | H17: KE644 | I17: 0.9375
B18: ASP211_OZB | C18: #완전특가 #마리나베이샌즈1박+4성호텔 #1일자유 #노쇼핑 #센토사루지 #슈퍼트리쇼 | D18: 싱-싱-싱 | E18: OZ751 | F18: 0.91319444 | H18: OZ752 | I18: 0.97916667
B19: ASP211_OZC | C19: #완전특가 #전일관광 #에메랄드힐 #센토사섬 #슈퍼트리쇼 #4성업그레이드 | D19: 싱-싱-싱 | E19: OZ751 | F19: 0.91319444 | H19: OZ752 | I19: 0.97916667
B20: ASP211_SQC | C20: 싱가포르 5일 #완전특가 #전일관광 #에메랄드힐 #센토사섬 #슈퍼트리쇼 #4성호텔 | D20: 싱-싱-싱 | E20: SQ607 | F20: 0.59375 | H20: SQ608 | I20: 0.0069444444
B21: ASP211_KEA | C21: #완전특가 #1일자유 #센토사루지 #슈퍼트리쇼 #4성업그레이드 | D21: 싱-싱-싱 | E21: KE0645 | F21: 0.98611111 | H21: KE0646 | I21: 0.048611111
B22: ASP211_USS
B23: ASP211_TW9 | C23: 싱가포르 5일 #전일관광 #센토사크루즈요트 #미식투어 #시티갤러리 #핵심관광지 #4성호텔 | D23: 싱-싱-싱 | E23: TW0161 | F23: 0.89583333 | H23: TW162 | I23: 0.95833333
B24: ASP212_SQA | C24: 싱가포르 5일 #4성호텔 #1일자유 #리버원더스 #센토사루지 #마담투소 #핵심관광지 #호텔뷔페 | D24: 싱-싱-싱 | E24: SQ607 | F24: 0.59722222 | H24: SQ608 | I24: 0.0069444444
B25: ASP212_OZD | C25: 싱가포르 5일#1일자유 #5성 아마라호텔 #센토사 루지 #마담투소 #리버원더스 #핵심관광지 #NO쇼핑 #NO 팁 | D25: 싱-싱-싱 | E25: OZ751 | F25: 0.91319444 | H25: OZ752 | I25: 0.97916667
B26: ASP213
B27: ASP215_OZB | C27: 싱가포르 5일#1일자유 #플라이어 #2층버스 #리버보트 #리버원더스 #5성호텔+마리나베이샌즈호텔 | D27: 싱-싱-싱 | E27: OZ751 | F27: 0.91319444 | H27: OZ752 | I27: 0.97916667
B28: ASP215_KEE | C28: 싱가포르 5일#센토사섬 #MBS스카이파크 #플라이어 #리버보트 #2층버스 #리버원더스 #5성호텔 | D28: 싱-싱-싱 | E28: KE645 | F28: 0.98611111 | H28: KE646 | I28: 0.048611111
B29: ASP309_SQ
B30: ASP310_7CB | C30: # 버드 파라다이스 #센토사 루지 #마담투소 #리버원더스 | D30: 싱-싱-싱 | E30: 7C4055 | F30: 0.97569444 | H30: 7C4056 | I30: 0.017361111
B31: ASP310_SQ
B32: ASP311_7CU | C32: [완전특가] 싱가포르 5일 #1일자유 #센토사 루지 #슈퍼트리쇼 #4성 업그레이드 | D32: 싱-싱-싱 | E32: 7C4055 | F32: 0.97569444 | H32: 7C4056 | I32: 0.017361111
B33: ASP311
B34: ASP311_7CX | C34: [완전특가 -전일관광] 싱가포르 5일#전일관광 #에메랄드힐 #센토사섬 #슈퍼트리쇼#4성업그레이드 | D34: 싱-싱-싱 | E34: 7C4055 | F34: 0.97569444 | H34: 7C4056 | I34: 0.017361111
B35: ASP312_7CU | C35: 싱가포르 5일#1일자유 #센토사 #가든스 바이더베이 #칠리크랩 #리버원더스 #4성호텔+마리나베이샌즈호텔 | E35: 7C4055 | F35: 0.97569444 | H35: 7C4056 | I35: 0.017361111
B36: ASP303_SQ | C36: 부산 출발 2박 4일 | D36: 싱-싱 | E36: SQ615 | F36: 0.54861111 | H36: SQ616 | I36: 0.96180556
B37: ASP910_TR | C37: 제주출발 | E37: TR0813 | F37: 0.59375
B38: ASP211_바탐
B39: ASP311_7CU_바탐 | C39: [완전특가] 바탐 1박 #센토사 루지 #슈퍼트리쇼 #4성 업그레이드 | D39: 싱-싱-싱 | E39: 7C4055 | F39: 0.97569444 | H39: 7C4056 | I39: 0.017361111
B40: ASP221_바탐_2박 | C40: 바탐 직항 6일 #바탐2박 #싱가포르2박 #라노섬투어 #마사지90분 #원주민마을 #싱가포르핵심투어 #센토사섬 | E40: 7C5301 | F40: 0.9375 | H40: 7C5302 | I40: 0.98958333
B41: 부산연합1 | C41: #NO옵션 #버드파라다이스 #핵심옵션포함 | E41: 7C4055 | F41: 0.97569444 | H41: 7C4056 | I41: 0.017361111
...

Sheet 초1
A1: home | E1: ='가이드&차량'!B1 -> 1100 | G1: 호텔 | H1: 트윈/더블 | I1: =C4/2 -> 15 | J1: 싱글 | K1: 0 | L1: 금액 | M1: 룸넘버 | N1: 소계 | O1: 합계 | V1: * 서차지기간 확인필수 | AC1: 주중 | AD1: 주말
B2: 마스터코드 | C2: 초등학교 글로벌 문화체험 1 | H2: =C5 -> 45979 | J2: =AB2 -> Aloft Novena | L2: =IF( (IF(WEEKDAY(H2, 2) <= 5, AC2, AD2) + IF(AND(H2 >= W3, H2 <= X3), Z3, 0) + IF(AND(H2 >= W4, H2 <= X4), Z4, 0) + IF(AND(H2 >= W5, H2 <= X5), Z5, 0) + IF(AND(H2 >= W6, H2 <= X6), Z6, 0) + IF(AND(H2 >= W7, H2 <= X7), Z7, 0) + IF(AND(H2 >= W8, H2 <= X8), Z8, 0) + IF(AND(H2 >= W9, H2 <= X9), Z9, 0) + IF(AND(H2 >= W10, H2 <= X10), Z10, 0) + IF(AND(H2 >= W11, H2 <= X11), Z11, 0) + IF(AND(H2 >= W12, H2 <= X12), Z12, 0) + IF(AND(H2 >= W13, H2 <= X13), Z13, 0) + IF(AND(H2 >= W14, H2 <= X14), Z14, 0) + IF(AND(H2 >= W15, H2 <= X15), Z15, 0) + IF(AND(H2 >= W16, H2 <= X16), Z16, 0) + IF(AND(H2 >= W17, H2 <= X17), Z17, 0) + IF(AND(H2 >= W18, H2 <= X18), Z18, 0) + IF(AND(H2 >= W19, H2 <= X19), Z19, 0) + IF(AND(H2 >= W20, H2 <= X20), Z20, 0) + IF(AND(H2 >= W21, H2 <= X21), Z21, 0) + IF(AND(H2 >= W22, H2 <= X22), Z22, 0) + IF(AND(H2 >= W23, H2 <= X23), Z23, 0) ) < 1, "Surcharge Check", (IF(WEEKDAY(H2, 2) <= 5, AC2, AD2) + IF(AND(H2 >= W3, H2 <= X3), Z3, 0) + IF(AND(H2 >= W4, H2 <= X4), Z4, 0) + IF(AND(H2 >= W5, H2 <= X5), Z5, 0) + IF(AND(H2 >= W6, H2 <= X6), Z6, 0) + IF(AND(H2 >= W7, H2 <= X7), Z7, 0) + IF(AND(H2 >= W8, H2 <= X8), Z8, 0) + IF(AND(H2 >= W9, H2 <= X9), Z9, 0) + IF(AND(H2 >= W10, H2 <= X10), Z10, 0) + IF(AND(H2 >= W11, H2 <= X11), Z11, 0) + IF(AND(H2 >= W12, H2 <= X12), Z12, 0) + IF(AND(H2 >= W13, H2 <= X13), Z13, 0) + IF(AND(H2 >= W14, H2 <= X14), Z14, 0) + IF(AND(H2 >= W15, H2 <= X15), Z15, 0) + IF(AND(H2 >= W16, H2 <= X16), Z16, 0) + IF(AND(H2 >= W17, H2 <= X17), Z17, 0) + IF(AND(H2 >= W18, H2 <= X18), Z18, 0) + IF(AND(H2 >= W19, H2 <= X19), Z19, 0) + IF(AND(H2 >= W20, H2 <= X20), Z20, 0) + IF(AND(H2 >= W21, H2 <= X21), Z21, 0) + IF(AND(H2 >= W22, H2 <= X22), Z22, 0) + IF(AND(H2 >= W23, H2 <= X23), Z23, 0) ) ) -> 180 | M2: =$I$1+$K$1 -> 15 | N2: =L2*M2 -> 2700 | O2: =SUM(N2:N6) -> 10800 | Q2: 옵션 - 5개 | R2: -40 | S2: 쇼핑 - 4회 | T2: -30 | V2: EVENT | W2: 시작일 | X2: 마감일 | Y2: 실제 행사일 | AB2: Aloft Novena | AC2: 180 | AD2: 180
B3: 구분[여정] | C3: #USS #만다이2Park #리버보트 #사이언스센터 | H3: =H2+1 -> 45980 | J3: =J2 -> Aloft Novena | L3: =IF( (IF(WEEKDAY(H3, 2) <= 5, AC2, AD2) + IF(AND(H3 >= W3, H3 <= X3), Z3, 0) + IF(AND(H3 >= W4, H3 <= X4), Z4, 0) + IF(AND(H3 >= W5, H3 <= X5), Z5, 0) + IF(AND(H3 >= W6, H3 <= X6), Z6, 0) + IF(AND(H3 >= W7, H3 <= X7), Z7, 0) + IF(AND(H3 >= W8, H3 <= X8), Z8, 0) + IF(AND(H3 >= W9, H3 <= X9), Z9, 0) + IF(AND(H3 >= W10, H3 <= X10), Z10, 0) + IF(AND(H3 >= W11, H3 <= X11), Z11, 0) + IF(AND(H3 >= W12, H3 <= X12), Z12, 0) + IF(AND(H3 >= W13, H3 <= X13), Z13, 0) + IF(AND(H3 >= W14, H3 <= X14), Z14, 0) + IF(AND(H3 >= W15, H3 <= X15), Z15, 0) + IF(AND(H3 >= W16, H3 <= X16), Z16, 0) + IF(AND(H3 >= W17, H3 <= X17), Z17, 0) + IF(AND(H3 >= W18, H3 <= X18), Z18, 0) + IF(AND(H3 >= W19, H3 <= X19), Z19, 0) + IF(AND(H3 >= W20, H3 <= X20), Z20, 0) + IF(AND(H3 >= W21, H3 <= X21), Z21, 0) + IF(AND(H3 >= W22, H3 <= X22), Z22, 0) + IF(AND(H3 >= W23, H3 <= X23), Z23, 0) ) < 1, "Surcharge Check", (IF(WEEKDAY(H3, 2) <= 5, AC2, AD2) + IF(AND(H3 >= W3, H3 <= X3), Z3, 0) + IF(AND(H3 >= W4, H3 <= X4), Z4, 0) + IF(AND(H3 >= W5, H3 <= X5), Z5, 0) + IF(AND(H3 >= W6, H3 <= X6), Z6, 0) + IF(AND(H3 >= W7, H3 <= X7), Z7, 0) + IF(AND(H3 >= W8, H3 <= X8), Z8, 0) + IF(AND(H3 >= W9, H3 <= X9), Z9, 0) + IF(AND(H3 >= W10, H3 <= X10), Z10, 0) + IF(AND(H3 >= W11, H3 <= X11), Z11, 0) + IF(AND(H3 >= W12, H3 <= X12), Z12, 0) + IF(AND(H3 >= W13, H3 <= X13), Z13, 0) + IF(AND(H3 >= W14, H3 <= X14), Z14, 0) + IF(AND(H3 >= W15, H3 <= X15), Z15, 0) + IF(AND(H3 >= W16, H3 <= X16), Z16, 0) + IF(AND(H3 >= W17, H3 <= X17), Z17, 0) + IF(AND(H3 >= W18, H3 <= X18), Z18, 0) + IF(AND(H3 >= W19, H3 <= X19), Z19, 0) + IF(AND(H3 >= W20, H3 <= X20), Z20, 0) + IF(AND(H3 >= W21, H3 <= X21), Z21, 0) + IF(AND(H3 >= W22, H3 <= X22), Z22, 0) + IF(AND(H3 >= W23, H3 <= X23), Z23, 0) ) ) -> 180 | M3: =$I$1+$K$1 -> 15 | N3: =L3*M3 -> 2700 | Q3: 옵션 - 4개 | R3: -30 | S3: 쇼핑 - 3회 | T3: -20 | V3: =서차지!B3 -> World Paralympic Swimming | W3: =서차지!C3 -> 45921 | X3: =서차지!D3 -> 45562 | Y3: =서차지!E3 -> 21 – 27 September 2025 | Z3: -2000
B4: 인원(손님) | C4: 30 | D4: 인원(FOC) | E4: 0 | H4: =H3+1 -> 45981 | J4: =J2 -> Aloft Novena | L4: =IF( (IF(WEEKDAY(H4, 2) <= 5, AC2, AD2) + IF(AND(H4 >= W3, H4 <= X3), Z3, 0) + IF(AND(H4 >= W4, H4 <= X4), Z4, 0) + IF(AND(H4 >= W5, H4 <= X5), Z5, 0) + IF(AND(H4 >= W6, H4 <= X6), Z6, 0) + IF(AND(H4 >= W7, H4 <= X7), Z7, 0) + IF(AND(H4 >= W8, H4 <= X8), Z8, 0) + IF(AND(H4 >= W9, H4 <= X9), Z9, 0) + IF(AND(H4 >= W10, H4 <= X10), Z10, 0) + IF(AND(H4 >= W11, H4 <= X11), Z11, 0) + IF(AND(H4 >= W12, H4 <= X12), Z12, 0) + IF(AND(H4 >= W13, H4 <= X13), Z13, 0) + IF(AND(H4 >= W14, H4 <= X14), Z14, 0) + IF(AND(H4 >= W15, H4 <= X15), Z15, 0) + IF(AND(H4 >= W16, H4 <= X16), Z16, 0) + IF(AND(H4 >= W17, H4 <= X17), Z17, 0) + IF(AND(H4 >= W18, H4 <= X18), Z18, 0) + IF(AND(H4 >= W19, H4 <= X19), Z19, 0) + IF(AND(H4 >= W20, H4 <= X20), Z20, 0) + IF(AND(H4 >= W21, H4 <= X21), Z21, 0) + IF(AND(H4 >= W22, H4 <= X22), Z22, 0) + IF(AND(H4 >= W23, H4 <= X23), Z23, 0) ) < 1, "Surcharge Check", (IF(WEEKDAY(H4, 2) <= 5, AC2, AD2) + IF(AND(H4 >= W3, H4 <= X3), Z3, 0) + IF(AND(H4 >= W4, H4 <= X4), Z4, 0) + IF(AND(H4 >= W5, H4 <= X5), Z5, 0) + IF(AND(H4 >= W6, H4 <= X6), Z6, 0) + IF(AND(H4 >= W7, H4 <= X7), Z7, 0) + IF(AND(H4 >= W8, H4 <= X8), Z8, 0) + IF(AND(H4 >= W9, H4 <= X9), Z9, 0) + IF(AND(H4 >= W10, H4 <= X10), Z10, 0) + IF(AND(H4 >= W11, H4 <= X11), Z11, 0) + IF(AND(H4 >= W12, H4 <= X12), Z12, 0) + IF(AND(H4 >= W13, H4 <= X13), Z13, 0) + IF(AND(H4 >= W14, H4 <= X14), Z14, 0) + IF(AND(H4 >= W15, H4 <= X15), Z15, 0) + IF(AND(H4 >= W16, H4 <= X16), Z16, 0) + IF(AND(H4 >= W17, H4 <= X17), Z17, 0) + IF(AND(H4 >= W18, H4 <= X18), Z18, 0) + IF(AND(H4 >= W19, H4 <= X19), Z19, 0) + IF(AND(H4 >= W20, H4 <= X20), Z20, 0) + IF(AND(H4 >= W21, H4 <= X21), Z21, 0) + IF(AND(H4 >= W22, H4 <= X22), Z22, 0) + IF(AND(H4 >= W23, H4 <= X23), Z23, 0) ) ) -> 180 | M4: =$I$1+$K$1 -> 15 | N4: =L4*M4 -> 2700 | Q4: 옵션 - 3개 | R4: -20 | S4: 쇼핑 - 2회 | T4: -10 | V4: =서차지!B4 -> Singapore Formula One (F1) | W4: =서차지!C4 -> 45932 | X4: =서차지!D4 -> 45935 | Y4: =서차지!E4 -> 02 Oct - 05 Oct, 2025 | Z4: -2000 | AB4: ='25메인호텔'!F2 -> Momentus | AC4: ='25메인호텔'!G2 -> 190 | AD4: ='25메인호텔'!H2 -> 180
B5: 도착날짜 | C5: 45979 | D5: 4 | E5: =C5+D5 -> 45983 | H5: =H4+1 -> 45982 | J5: =J2 -> Aloft Novena | L5: =IF( (IF(WEEKDAY(H5, 2) <= 5, AC2, AD2) + IF(AND(H5 >= W3, H5 <= X3), Z3, 0) + IF(AND(H5 >= W4, H5 <= X4), Z4, 0) + IF(AND(H5 >= W5, H5 <= X5), Z5, 0) + IF(AND(H5 >= W6, H5 <= X6), Z6, 0) + IF(AND(H5 >= W7, H5 <= X7), Z7, 0) + IF(AND(H5 >= W8, H5 <= X8), Z8, 0) + IF(AND(H5 >= W9, H5 <= X9), Z9, 0) + IF(AND(H5 >= W10, H5 <= X10), Z10, 0) + IF(AND(H5 >= W11, H5 <= X11), Z11, 0) + IF(AND(H5 >= W12, H5 <= X12), Z12, 0) + IF(AND(H5 >= W13, H5 <= X13), Z13, 0) + IF(AND(H5 >= W14, H5 <= X14), Z14, 0) + IF(AND(H5 >= W15, H5 <= X15), Z15, 0) + IF(AND(H5 >= W16, H5 <= X16), Z16, 0) + IF(AND(H5 >= W17, H5 <= X17), Z17, 0) + IF(AND(H5 >= W18, H5 <= X18), Z18, 0) + IF(AND(H5 >= W19, H5 <= X19), Z19, 0) + IF(AND(H5 >= W20, H5 <= X20), Z20, 0) + IF(AND(H5 >= W21, H5 <= X21), Z21, 0) + IF(AND(H5 >= W22, H5 <= X22), Z22, 0) + IF(AND(H5 >= W23, H5 <= X23), Z23, 0) ) < 1, "Surcharge Check", (IF(WEEKDAY(H5, 2) <= 5, AC2, AD2) + IF(AND(H5 >= W3, H5 <= X3), Z3, 0) + IF(AND(H5 >= W4, H5 <= X4), Z4, 0) + IF(AND(H5 >= W5, H5 <= X5), Z5, 0) + IF(AND(H5 >= W6, H5 <= X6), Z6, 0) + IF(AND(H5 >= W7, H5 <= X7), Z7, 0) + IF(AND(H5 >= W8, H5 <= X8), Z8, 0) + IF(AND(H5 >= W9, H5 <= X9), Z9, 0) + IF(AND(H5 >= W10, H5 <= X10), Z10, 0) + IF(AND(H5 >= W11, H5 <= X11), Z11, 0) + IF(AND(H5 >= W12, H5 <= X12), Z12, 0) + IF(AND(H5 >= W13, H5 <= X13), Z13, 0) + IF(AND(H5 >= W14, H5 <= X14), Z14, 0) + IF(AND(H5 >= W15, H5 <= X15), Z15, 0) + IF(AND(H5 >= W16, H5 <= X16), Z16, 0) + IF(AND(H5 >= W17, H5 <= X17), Z17, 0) + IF(AND(H5 >= W18, H5 <= X18), Z18, 0) + IF(AND(H5 >= W19, H5 <= X19), Z19, 0) + IF(AND(H5 >= W20, H5 <= X20), Z20, 0) + IF(AND(H5 >= W21, H5 <= X21), Z21, 0) + IF(AND(H5 >= W22, H5 <= X22), Z22, 0) + IF(AND(H5 >= W23, H5 <= X23), Z23, 0) ) ) -> 180 | M5: =$I$1+$K$1 -> 15 | N5: =L5*M5 -> 2700 | Q5: 옵션 - 2개 | R5: 0 | S5: 쇼핑 - 1회 | T5: 0 | V5: =서차지!B5 -> ITB Asia | W5: =서차지!C5 -> 45944 | X5: =서차지!D5 -> 45947 | Y5: =서차지!E5 -> 23 - 25 October 2025 | Z5: -2000 | AB5: ='25메인호텔'!F3 -> Aloft Novena | AC5: ='25메인호텔'!G3 -> 180 | AD5: ='25메인호텔'!H3 -> 180
B6: 인당 지상비 (SGD) | C6: =(SUM(O10:O40)+O2)/C4+R6+T6 -> 848.06667 | D6: 인당 지상비 (원화) | E6: =C6*$E$1 -> 932873.33 | L6: =IF( (IF(WEEKDAY(H6, 2) <= 5, AC2, AD2) + IF(AND(H6 >= W3, H6 <= X3), Z3, 0) + IF(AND(H6 >= W4, H6 <= X4), Z4, 0) + IF(AND(H6 >= W5, H6 <= X5), Z5, 0) + IF(AND(H6 >= W6, H6 <= X6), Z6, 0) + IF(AND(H6 >= W7, H6 <= X7), Z7, 0) + IF(AND(H6 >= W8, H6 <= X8), Z8, 0) + IF(AND(H6 >= W9, H6 <= X9), Z9, 0) + IF(AND(H6 >= W10, H6 <= X10), Z10, 0) + IF(AND(H6 >= W11, H6 <= X11), Z11, 0) + IF(AND(H6 >= W12, H6 <= X12), Z12, 0) + IF(AND(H6 >= W13, H6 <= X13), Z13, 0) + IF(AND(H6 >= W14, H6 <= X14), Z14, 0) + IF(AND(H6 >= W15, H6 <= X15), Z15, 0) + IF(AND(H6 >= W16, H6 <= X16), Z16, 0) + IF(AND(H6 >= W17, H6 <= X17), Z17, 0) + IF(AND(H6 >= W18, H6 <= X18), Z18, 0) + IF(AND(H6 >= W19, H6 <= X19), Z19, 0) + IF(AND(H6 >= W20, H6 <= X20), Z20, 0) + IF(AND(H6 >= W21, H6 <= X21), Z21, 0) + IF(AND(H6 >= W22, H6 <= X22), Z22, 0) + IF(AND(H6 >= W23, H6 <= X23), Z23, 0) ) < 1, "Surcharge Check", (IF(WEEKDAY(H6, 2) <= 5, AC2, AD2) + IF(AND(H6 >= W3, H6 <= X3), Z3, 0) + IF(AND(H6 >= W4, H6 <= X4), Z4, 0) + IF(AND(H6 >= W5, H6 <= X5), Z5, 0) + IF(AND(H6 >= W6, H6 <= X6), Z6, 0) + IF(AND(H6 >= W7, H6 <= X7), Z7, 0) + IF(AND(H6 >= W8, H6 <= X8), Z8, 0) + IF(AND(H6 >= W9, H6 <= X9), Z9, 0) + IF(AND(H6 >= W10, H6 <= X10), Z10, 0) + IF(AND(H6 >= W11, H6 <= X11), Z11, 0) + IF(AND(H6 >= W12, H6 <= X12), Z12, 0) + IF(AND(H6 >= W13, H6 <= X13), Z13, 0) + IF(AND(H6 >= W14, H6 <= X14), Z14, 0) + IF(AND(H6 >= W15, H6 <= X15), Z15, 0) + IF(AND(H6 >= W16, H6 <= X16), Z16, 0) + IF(AND(H6 >= W17, H6 <= X17), Z17, 0) + IF(AND(H6 >= W18, H6 <= X18), Z18, 0) + IF(AND(H6 >= W19, H6 <= X19), Z19, 0) + IF(AND(H6 >= W20, H6 <= X20), Z20, 0) + IF(AND(H6 >= W21, H6 <= X21), Z21, 0) + IF(AND(H6 >= W22, H6 <= X22), Z22, 0) + IF(AND(H6 >= W23, H6 <= X23), Z23, 0) ) ) -> 180 | Q6: 옵션 - 0개 | R6: 5 | S6: 쇼핑 - 0회 | T6: 5 | V6: =서차지!B6 -> FHA-HoReCa | W6: =서차지!C6 -> 45950 | X6: =서차지!D6 -> 45953 | Y6: =서차지!E6 -> 0 | Z6: -2000 | AB6: ='25메인호텔'!F4 -> Mercure Stevens | AC6: ='25메인호텔'!G4 -> 180 | AD6: ='25메인호텔'!H4 -> 180
B7: 옵션 | C7: 0 | D7: 쇼핑 | E7: 0 | V7: =서차지!B7 -> FinTech 2025 | W7: =서차지!C7 -> 45972 | X7: =서차지!D7 -> 45974 | Y7: =서차지!E7 -> 0 | Z7: -2000 | AB7: ='25메인호텔'!F5 -> M Hotel City Centre | AC7: ='25메인호텔'!G5 -> 230 | AD7: ='25메인호텔'!H5 -> 230
G8: 입장료(항공) | I8: 식사비 | K8: 차량 | M8: 가이드 | O8: 총합계 | V8: =서차지!B8 -> Christmas Day | W8: =서차지!C8 -> 46015 | X8: =서차지!D8 -> 46016 | Y8: =서차지!E8 -> 0 | Z8: -2000 | AB8: ='25메인호텔'!F6 -> Concorde Hotel | AC8: ='25메인호텔'!G6 -> 230 | AD8: ='25메인호텔'!H6 -> 230
B9: SGD/WON | C9: =E1 -> 1100 | D9: SGD/MYR | E9: 3.5 | G9: 금액 | H9: 인원 | I9: 금액 | J9: 인원 | K9: 금액 | L9: 인원 | M9: 금액 | N9: 인원 | V9: =서차지!B9 -> Year End | W9: =서차지!C9 -> 46021 | X9: =서차지!D9 -> 46023 | Y9: =서차지!E9 -> 0 | Z9: -2000 | AB9: ='25메인호텔'!F7 -> Oasia Novena | AC9: ='25메인호텔'!G7 -> 210 | AD9: ='25메인호텔'!H7 -> 210
B10: =TEXT(C5,"m월 d일 aaaa") -> 11월 18일 화요일 | C10: 인천출발 - 싱가포르 도착 | E10: =상품리스트!F3 -> 0 | K10: =IF(C4+E4<8,'가이드&차량'!C43, IF(C4+E4<=14,'가이드&차량'!C35,'가이드&차량'!C19)) -> 280 | L10: 1 | M10: ='가이드&차량'!C3 -> 150 | N10: 1 | O10: =(G10*H10)+(I10*J10)+(K10*L10)+(M10*N10) -> 430 | V10: =서차지!B10 -> Year End | W10: =서차지!C10 -> 46022 | X10: =서차지!D10 -> 46022 | Y10: =서차지!E10 -> 0 | Z10: -2000 | AB10: ='25메인호텔'!F8 -> Orchid Hotel | AC10: ='25메인호텔'!G8 -> 220 | AD10: ='25메인호텔'!H8 -> 220
C11: 가이드 미팅 후 싱가포르 호텔 이동 | O11: =(G11*H11)+(I11*J11)+(K11*L11)+(M11*N11) -> 0 | V11: =서차지!B11 -> Singapore Airshow 2026 | W11: =서차지!C11 -> 46056 | X11: =서차지!D11 -> 46059 | Y11: =서차지!E11 -> 3 - 6 Feb 2026 | AB11: ='25메인호텔'!F9 -> Amara Singapore | AC11: ='25메인호텔'!G9 -> 230 | AD11: ='25메인호텔'!H9 -> 230
C12: 싱가포르 호텔 투숙 | O12: =(G12*H12)+(I12*J12)+(K12*L12)+(M12*N12) -> 0 | V12: =서차지!B12 -> Chinese New Year | W12: =서차지!C12 -> 46069 | X12: =서차지!D12 -> 46077 | Y12: =서차지!E12 -> 16 - 24 Feb 2026 | AB12: ='25메인호텔'!F10 -> Orchard Hotel | AC12: ='25메인호텔'!G10 -> 240 | AD12: ='25메인호텔'!H10 -> 240
B13: =TEXT(C5+1,"m월 d일 aaaa") -> 11월 19일 수요일 | C13: 호텔 조식 후 가이드 미팅 | K13: =IF(C4+E4<8,'가이드&차량'!C47, IF(C4+E4<=14,'가이드&차량'!C39,'가이드&차량'!C23)) -> 630 | L13: =L10 -> 1 | M13: ='가이드&차량'!C6 -> 375 | N13: 1 | O13: =(G13*H13)+(I13*J13)+(K13*L13)+(M13*N13) -> 1005 | Q13: 차량/가이드 10시간 기준 | V13: =서차지!B13 -> Food & Hotel Beverage | W13: =서차지!C13 -> 0 | X13: =서차지!D13 -> 0 | Y13: =서차지!E13 -> 0 | AB13: ='25메인호텔'!F11 -> Grand Copthorne | AC13: ='25메인호텔'!G11 -> 240 | AD13: ='25메인호텔'!H11 -> 240
C14: 리버원더스 | G14: =일정!E38 -> 23.5 | H14: =$C$4+$E$4 -> 30 | O14: =(G14*H14)+(I14*J14)+(K14*L14)+(M14*N14) -> 705 | V14: =서차지!B14 -> CommunicAsia | W14: =서차지!C14 -> 0 | X14: =서차지!D14 -> 0 | Y14: =서차지!E14 -> 0 | AB14: ='25메인호텔'!F12 -> Mercure Tyrwhitt | AC14: ='25메인호텔'!G12 -> 170 | AD14: ='25메인호텔'!H12 -> 170
C15: (중식) 페라나카식 | I15: =식사!E21 -> 18 | J15: =$C$4+$E$4 -> 30 | O15: =(G15*H15)+(I15*J15)+(K15*L15)+(M15*N15) -> 540 | V15: =서차지!B15 -> National Day | W15: =서차지!C15 -> 0 | X15: =서차지!D15 -> 0 | Y15: =서차지!E15 -> 0 | AB15: ='25메인호텔'!F13 -> Hotel Boss | AC15: ='25메인호텔'!G13 -> 185 | AD15: ='25메인호텔'!H13 -> 185
C16: 머라이언 공원+에스플라네이드 | O16: =(G16*H16)+(I16*J16)+(K16*L16)+(M16*N16) -> 0 | AB16: ='25메인호텔'!F14 -> V Hotel Lavender | AC16: ='25메인호텔'!G14 -> 185 | AD16: ='25메인호텔'!H14 -> 185
C17: =일정!C27 -> 가든스바이더베이 2돔 ( 쥬랴기 ) | G17: =일정!E27 -> 28.3 | H17: =$C$4+$E$4 -> 30 | O17: =(G17*H17)+(I17*J17)+(K17*L17)+(M17*N17) -> 849 | AB17: ='25메인호텔'!F15 -> IbIs Novena | AC17: ='25메인호텔'!G15 -> 155 | AD17: ='25메인호텔'!H15 -> 155
C18: (석식) 오빠샤브- 스팀보트 +한식 뷔페 | I18: =식사!E7 -> 18 | J18: =$C$4+$E$4 -> 30 | O18: =(G18*H18)+(I18*J18)+(K18*L18)+(M18*N18) -> 540 | AB18: ='25메인호텔'!F16 -> IbIs bencoolen | AC18: ='25메인호텔'!G16 -> 185 | AD18: ='25메인호텔'!H16 -> 185
C19: 리버보트 탑승 + 슈퍼트리쇼 | G19: =일정!E30 -> 15 | H19: =$C$4+$E$4 -> 30 | O19: =(G19*H19)+(I19*J19)+(K19*L19)+(M19*N19) -> 450 | AB19: ='25메인호텔'!F17 -> Oasia Sentosa | AC19: ='25메인호텔'!G17 -> 240 | AD19: ='25메인호텔'!H17 -> 240
C20: 호텔 복귀 휴식 및 취침 | O20: =(G20*H20)+(I20*J20)+(K20*L20)+(M20*N20) -> 0 | AB20: ='25메인호텔'!F18 -> Swissotel The stamford | AC20: ='25메인호텔'!G18 -> 540 | AD20: ='25메인호텔'!H18 -> 540 | AE20: ='25메인호텔'!#REF! -> #REF! | AF20: ='25메인호텔'!#REF! -> #REF!
B21: =TEXT(C5+2,"m월 d일 aaaa") -> 11월 20일 목요일 | C21: 호텔 조식 후 가이드 미팅 | K21: =IF(C4+E4<8,'가이드&차량'!C47, IF(C4+E4<=14,'가이드&차량'!C39,'가이드&차량'!C23)) -> 630 | L21: =L10 -> 1 | M21: ='가이드&차량'!C6 -> 375 | N21: =N10 -> 1 | O21: =(G21*H21)+(I21*J21)+(K21*L21)+(M21*N21) -> 1005 | Q21: 차량/가이드 10시간 기준
C22: USS 자유 관람 | G22: =일정!E3 -> 75.3 | H22: =$C$4+$E$4 -> 30 | O22: =(G22*H22)+(I22*J22)+(K22*L22)+(M22*N22) -> 2259
C23: (중식) 자유식 20 SGD | I23: 20 | J23: =$C$4+$E$4 -> 30 | O23: =(G23*H23)+(I23*J23)+(K23*L23)+(M23*N23) -> 600
C24: (석식) 한식당 - 고기집(부대찌게+불고기세트) | I24: =식사!E15 -> 18 | J24: =$C$4+$E$4 -> 30 | O24: =(G24*H24)+(I24*J24)+(K24*L24)+(M24*N24) -> 540
C25: 호텔 수영장 | O25: =(G25*H25)+(I25*J25)+(K25*L25)+(M25*N25) -> 0
C26: 호텔 복귀 휴식 및 취침 | O26: =(G26*H26)+(I26*J26)+(K26*L26)+(M26*N26) -> 0
B27: =TEXT(C5+3,"m월 d일 aaaa") -> 11월 21일 금요일 | C27: 호텔 조식 후 가이드 미팅 | K27: =IF(C4+E4<8,'가이드&차량'!C47, IF(C4+E4<=14,'가이드&차량'!C39,'가이드&차량'!C23)) -> 630 | L27: =L10 -> 1 | M27: ='가이드&차량'!C6 -> 375 | N27: =N10 -> 1 | O27: =(G27*H27)+(I27*J27)+(K27*L27)+(M27*N27) -> 1005 | Q27: 차량/가이드 12시간 기준
C28: 버드파라다이스 | G28: =일정!E40 -> 24.5 | H28: =$C$4+$E$4 -> 30 | O28: =(G28*H28)+(I28*J28)+(K28*L28)+(M28*N28) -> 735
C29: (중식) 팽귄코브 | I29: =식사!E36 -> 20 | J29: =$C$4+$E$4 -> 30 | O29: =(G29*H29)+(I29*J29)+(K29*L29)+(M29*N29) -> 600
C30: 싱가포르 사이언스 센터 | G30: =일정!E34 -> 8.3 | H30: =$C$4+$E$4 -> 30 | O30: =(G30*H30)+(I30*J30)+(K30*L30)+(M30*N30) -> 249
C31: 비보시티 | O31: =(G31*H31)+(I31*J31)+(K31*L31)+(M31*N31) -> 0
C32: (석식) 비보시티 자유식 | I32: 20 | J32: =$C$4+$E$4 -> 30 | O32: =(G32*H32)+(I32*J32)+(K32*L32)+(M32*N32) -> 600
C33: 호텔 수영장 | O33: =(G33*H33)+(I33*J33)+(K33*L33)+(M33*N33) -> 0
C34: 호텔 복귀 휴식 및 취침 | O34: =(G34*H34)+(I34*J34)+(K34*L34)+(M34*N34) -> 0
B35: =TEXT(C5+4,"m월 d일 aaaa") -> 11월 22일 토요일 | C35: 호텔 조식 후 체크아웃 | K35: =IF(C4+E4<8,'가이드&차량'!C43, IF(C4+E4<=14,'가이드&차량'!C35,'가이드&차량'!C19)) -> 280 | L35: =L10 -> 1 | M35: ='가이드&차량'!C3 -> 150 | N35: =N10 -> 1 | O35: =(G35*H35)+(I35*J35)+(K35*L35)+(M35*N35) -> 430 | Q35: 차량/가이드 12시간 기준
C36: 공항 이동 후 출국 | E36: =상품리스트!I5 -> 0 | O36: =(G36*H36)+(I36*J36)+(K36*L36)+(M36*N36) -> 0
K37: =SUM(K10:K34) -> 2170 | M37: =SUM(M10:M34) -> 1275
B38: 기타비용 | C38: 기타 예비 비용 ( 1일 1인 생수 등) | G38: =$C$4+$E$4 -> 30 | I38: 10 | K38: 1 | O38: =G38*I38*K38 -> 300
C39: 핸들링차지 | G39: 50 | K39: =C4 -> 30 | O39: =G39*K39 -> 1500

Sheet 초2
A1: home | E1: ='가이드&차량'!B1 -> 1100 | G1: 호텔 | H1: 트윈/더블 | I1: =C4/2 -> 15 | J1: 싱글 | K1: 0 | L1: 금액 | M1: 룸넘버 | N1: 소계 | O1: 합계 | V1: * 서차지기간 확인필수 | AC1: 주중 | AD1: 주말
B2: 마스터코드 | C2: 초등학교 글로벌 문화체험 2 | H2: =C5 -> 45732 | J2: =AB2 -> Aloft Novena | L2: =IF( (IF(WEEKDAY(H2, 2) <= 5, AC2, AD2) + IF(AND(H2 >= W3, H2 <= X3), Z3, 0) + IF(AND(H2 >= W4, H2 <= X4), Z4, 0) + IF(AND(H2 >= W5, H2 <= X5), Z5, 0) + IF(AND(H2 >= W6, H2 <= X6), Z6, 0) + IF(AND(H2 >= W7, H2 <= X7), Z7, 0) + IF(AND(H2 >= W8, H2 <= X8), Z8, 0) + IF(AND(H2 >= W9, H2 <= X9), Z9, 0) + IF(AND(H2 >= W10, H2 <= X10), Z10, 0)) < 1, "Surcharge Check", (IF(WEEKDAY(H2, 2) <= 5, AC2, AD2) + IF(AND(H2 >= W3, H2 <= X3), Z3, 0) + IF(AND(H2 >= W4, H2 <= X4), Z4, 0) + IF(AND(H2 >= W5, H2 <= X5), Z5, 0) + IF(AND(H2 >= W6, H2 <= X6), Z6, 0) + IF(AND(H2 >= W7, H2 <= X7), Z7, 0) + IF(AND(H2 >= W8, H2 <= X8), Z8, 0) + IF(AND(H2 >= W9, H2 <= X9), Z9, 0) + IF(AND(H2 >= W10, H2 <= X10), Z10, 0)) ) -> 180 | M2: =$I$1+$K$1 -> 15 | N2: =L2*M2 -> 2700 | O2: =SUM(N2:N6) -> 8100 | Q2: 옵션 - 5개 | R2: -40 | S2: 쇼핑 - 4회 | T2: -30 | V2: EVENT | W2: 시작일 | X2: 마감일 | Y2: 실제 행사일 | AB2: Aloft Novena | AC2: 180 | AD2: 180
B3: 구분[여정] | C3: #USS #리버원더스 #사이언스센터 #스카이파크 | H3: =H2+1 -> 45733 | J3: =J2 -> Aloft Novena | L3: =IF( (IF(WEEKDAY(H3, 2) <= 5, AC2, AD2) + IF(AND(H3 >= W3, H3 <= X3), Z3, 0) + IF(AND(H3 >= W4, H3 <= X4), Z4, 0) + IF(AND(H3 >= W5, H3 <= X5), Z5, 0) + IF(AND(H3 >= W6, H3 <= X6), Z6, 0) + IF(AND(H3 >= W7, H3 <= X7), Z7, 0) + IF(AND(H3 >= W8, H3 <= X8), Z8, 0) + IF(AND(H3 >= W9, H3 <= X9), Z9, 0) + IF(AND(H3 >= W10, H3 <= X10), Z10, 0)) < 1, "Surcharge Check", (IF(WEEKDAY(H3, 2) <= 5, AC2, AD2) + IF(AND(H3 >= W3, H3 <= X3), Z3, 0) + IF(AND(H3 >= W4, H3 <= X4), Z4, 0) + IF(AND(H3 >= W5, H3 <= X5), Z5, 0) + IF(AND(H3 >= W6, H3 <= X6), Z6, 0) + IF(AND(H3 >= W7, H3 <= X7), Z7, 0) + IF(AND(H3 >= W8, H3 <= X8), Z8, 0) + IF(AND(H3 >= W9, H3 <= X9), Z9, 0) + IF(AND(H3 >= W10, H3 <= X10), Z10, 0)) ) -> 180 | M3: =$I$1+$K$1 -> 15 | N3: =L3*M3 -> 2700 | Q3: 옵션 - 4개 | R3: -30 | S3: 쇼핑 - 3회 | T3: -20 | V3: =서차지!B3 -> World Paralympic Swimming | W3: =서차지!C3 -> 45921 | X3: =서차지!D3 -> 45562 | Y3: =서차지!E3 -> 21 – 27 September 2025 | Z3: -2000
B4: 인원(손님) | C4: 30 | D4: 인원(FOC) | H4: =H3+1 -> 45734 | J4: =J2 -> Aloft Novena | L4: =IF( (IF(WEEKDAY(H4, 2) <= 5, AC2, AD2) + IF(AND(H4 >= W3, H4 <= X3), Z3, 0) + IF(AND(H4 >= W4, H4 <= X4), Z4, 0) + IF(AND(H4 >= W5, H4 <= X5), Z5, 0) + IF(AND(H4 >= W6, H4 <= X6), Z6, 0) + IF(AND(H4 >= W7, H4 <= X7), Z7, 0) + IF(AND(H4 >= W8, H4 <= X8), Z8, 0) + IF(AND(H4 >= W9, H4 <= X9), Z9, 0) + IF(AND(H4 >= W10, H4 <= X10), Z10, 0)) < 1, "Surcharge Check", (IF(WEEKDAY(H4, 2) <= 5, AC2, AD2) + IF(AND(H4 >= W3, H4 <= X3), Z3, 0) + IF(AND(H4 >= W4, H4 <= X4), Z4, 0) + IF(AND(H4 >= W5, H4 <= X5), Z5, 0) + IF(AND(H4 >= W6, H4 <= X6), Z6, 0) + IF(AND(H4 >= W7, H4 <= X7), Z7, 0) + IF(AND(H4 >= W8, H4 <= X8), Z8, 0) + IF(AND(H4 >= W9, H4 <= X9), Z9, 0) + IF(AND(H4 >= W10, H4 <= X10), Z10, 0)) ) -> 180 | M4: =$I$1+$K$1 -> 15 | N4: =L4*M4 -> 2700 | Q4: 옵션 - 3개 | R4: -20 | S4: 쇼핑 - 2회 | T4: -10 | V4: =서차지!B4 -> Singapore Formula One (F1) | W4: =서차지!C4 -> 45932 | X4: =서차지!D4 -> 45935 | Y4: =서차지!E4 -> 02 Oct - 05 Oct, 2025 | Z4: -2000 | AB4: ='25메인호텔'!F2 -> Momentus | AC4: ='25메인호텔'!G2 -> 190 | AD4: ='25메인호텔'!H2 -> 180
B5: 도착날짜 | C5: 45732 | D5: 3 | E5: =C5+D5 -> 45735 | Q5: 옵션 - 2개 | R5: 0 | S5: 쇼핑 - 1회 | T5: 0 | V5: =서차지!B5 -> ITB Asia | W5: =서차지!C5 -> 45944 | X5: =서차지!D5 -> 45947 | Y5: =서차지!E5 -> 23 - 25 October 2025 | Z5: -2000 | AB5: ='25메인호텔'!F3 -> Aloft Novena | AC5: ='25메인호텔'!G3 -> 180 | AD5: ='25메인호텔'!H3 -> 180
B6: 인당 지상비 (SGD) | C6: =(SUM(O10:O41)+O2)/C4+R6+T6 -> 862.03333 | D6: 인당 지상비 (원화) | E6: =C6*$E$1 -> 948236.67 | Q6: 옵션 - 0개 | R6: 5 | S6: 쇼핑 - 0회 | T6: 5 | V6: =서차지!B6 -> FHA-HoReCa | W6: =서차지!C6 -> 45950 | X6: =서차지!D6 -> 45953 | Y6: =서차지!E6 -> 0 | Z6: -2000 | AB6: ='25메인호텔'!F4 -> Mercure Stevens | AC6: ='25메인호텔'!G4 -> 180 | AD6: ='25메인호텔'!H4 -> 180
B7: 옵션 | C7: 0 | D7: 쇼핑 | E7: 0 | V7: =서차지!B7 -> FinTech 2025 | W7: =서차지!C7 -> 45972 | X7: =서차지!D7 -> 45974 | Y7: =서차지!E7 -> 0 | Z7: -2000 | AB7: ='25메인호텔'!F5 -> M Hotel City Centre | AC7: ='25메인호텔'!G5 -> 230 | AD7: ='25메인호텔'!H5 -> 230
G8: 입장료(항공) | I8: 식사비 | K8: 차량 | M8: 가이드 | O8: 총합계 | V8: =서차지!B8 -> Christmas Day | W8: =서차지!C8 -> 46015 | X8: =서차지!D8 -> 46016 | Y8: =서차지!E8 -> 0 | Z8: -2000 | AB8: ='25메인호텔'!F6 -> Concorde Hotel | AC8: ='25메인호텔'!G6 -> 230 | AD8: ='25메인호텔'!H6 -> 230
B9: SGD/WON | C9: =E1 -> 1100 | D9: SGD/MYR | E9: 3.5 | G9: 금액 | H9: 인원 | I9: 금액 | J9: 인원 | K9: 금액 | L9: 인원 | M9: 금액 | N9: 인원 | V9: =서차지!B9 -> Year End | W9: =서차지!C9 -> 46021 | X9: =서차지!D9 -> 46023 | Y9: =서차지!E9 -> 0 | Z9: -2000 | AB9: ='25메인호텔'!F7 -> Oasia Novena | AC9: ='25메인호텔'!G7 -> 210 | AD9: ='25메인호텔'!H7 -> 210
B10: =TEXT(C5,"m월 d일 aaaa") -> 3월 16일 일요일 | C10: 인천출발 - 싱가포르 도착 | E10: =상품리스트!F4 -> 0 | K10: =IF(C4+E4<8,'가이드&차량'!C43, IF(C4+E4<=14,'가이드&차량'!C35,'가이드&차량'!C19)) -> 280 | L10: 1 | M10: ='가이드&차량'!C3 -> 150 | N10: 1 | O10: =(G10*H10)+(I10*J10)+(K10*L10)+(M10*N10) -> 430 | V10: =서차지!B10 -> Year End | W10: =서차지!C10 -> 46022 | X10: =서차지!D10 -> 46022 | Y10: =서차지!E10 -> 0 | Z10: -2000 | AB10: ='25메인호텔'!F8 -> Orchid Hotel | AC10: ='25메인호텔'!G8 -> 220 | AD10: ='25메인호텔'!H8 -> 220
C11: 가이드 미팅 후 싱가포르 호텔 이동 | O11: =(G11*H11)+(I11*J11)+(K11*L11)+(M11*N11) -> 0 | V11: =서차지!B11 -> Singapore Airshow 2026 | W11: =서차지!C11 -> 46056 | X11: =서차지!D11 -> 46059 | Y11: =서차지!E11 -> 3 - 6 Feb 2026 | AB11: ='25메인호텔'!F9 -> Amara Singapore | AC11: ='25메인호텔'!G9 -> 230 | AD11: ='25메인호텔'!H9 -> 230
C12: 싱가포르 호텔 투숙 | O12: =(G12*H12)+(I12*J12)+(K12*L12)+(M12*N12) -> 0 | V12: =서차지!B12 -> Chinese New Year | W12: =서차지!C12 -> 46069 | X12: =서차지!D12 -> 46077 | Y12: =서차지!E12 -> 16 - 24 Feb 2026 | AB12: ='25메인호텔'!F10 -> Orchard Hotel | AC12: ='25메인호텔'!G10 -> 240 | AD12: ='25메인호텔'!H10 -> 240
